Workbook
Name \Z: #REF!
Name \Z: #REF!
Name \Z: #REF!
Name \Z: #REF!
Name \Z: #REF!
Name \Z: #REF!
Name \Z: #REF!
Name \Z: #REF!
Name \Z: #REF!
Name \Z: #REF!
Name \Z: #REF!
Name \Z: #REF!
Name \Z: #REF!
Name \Z: #REF!
Name \Z: #REF!
Name \Z: #REF!
Name \Z: #REF!
Name \Z: #REF!
Name \Z: #REF!
Name \Z: #REF!
Name \Z: #REF!
Name \Z: #REF!
Name \Z: #REF!
Name \Z: #REF!
Name \Z: #REF!
Name \Z: #REF!
Name \Z: #REF!
Name \Z: #REF!
Name ________MTH06: [1]Paramter!$A$16:$A$27
Name _______MTH06: [1]Paramter!$A$16:$A$27
Name ______MTH06: [1]Paramter!$A$16:$A$27
Name _____MTH06: [2]Paramter!$A$16:$A$27
Name _____MTH06: [2]Paramter!$A$16:$A$27
Name _____MTH06: [2]Paramter!$A$16:$A$27
Name _____MTH06: [2]Paramter!$A$16:$A$27
Name _____MTH06: [2]Paramter!$A$16:$A$27
Name _____MTH06: [2]Paramter!$A$16:$A$27
Name _____MTH06: [2]Paramter!$A$16:$A$27
Name _____MTH06: [2]Paramter!$A$16:$A$27
Name _____MTH06: [2]Paramter!$A$16:$A$27
Name _____MTH06: [2]Paramter!$A$16:$A$27
Name _____MTH06: [2]Paramter!$A$16:$A$27
Name _____MTH06: [2]Paramter!$A$16:$A$27
Name _____MTH06: [2]Paramter!$A$16:$A$27
Name _____MTH06: [2]Paramter!$A$16:$A$27
Name _____MTH06: [2]Paramter!$A$16:$A$27
Name _____MTH06: [2]Paramter!$A$16:$A$27
Name _____MTH06: [2]Paramter!$A$16:$A$27
Name _____MTH06: [2]Paramter!$A$16:$A$27
Name _____MTH06: [2]Paramter!$A$16:$A$27
Name _____MTH06: [2]Paramter!$A$16:$A$27
Name _____MTH06: [2]Paramter!$A$16:$A$27
Name _____MTH06: [3]Paramter!$A$16:$A$27
Name _____MTH06: [3]Paramter!$A$16:$A$27
Name ____MTH06: [2]Paramter!$A$16:$A$27
Name ____MTH06: [2]Paramter!$A$16:$A$27
Name ____MTH06: [2]Paramter!$A$16:$A$27
Name ____MTH06: [2]Paramter!$A$16:$A$27
Name ____MTH06: [2]Paramter!$A$16:$A$27
Name ____MTH06: [2]Paramter!$A$16:$A$27

Sheet Account
A1: PRC编码 | B1: PRC名称 | C1: HK code | D1: HK Account Name | E1: 全名 | G1: 余额方向 | H1: 科目类别 | I1: 外币核算 | J1: 核算维度 | K1: 数据状态
A2: 1001 | B2: 库存现金 | E2: 库存现金 | F2: Cash On Hand | G2: 借方 | H2: 流动资产 | K2: 已审核
A3: 1002 | B3: 银行存款 | E3: 银行存款 | F3: Bank Deposit | G3: 借方 | H3: 流动资产 | I3: 所有币别 | K3: 已审核
A4: 1002.01 | B4: 【旭智资本】银行存款账户 | E4: 银行存款_【旭智资本】银行存款账户 | F4: ACPL Bank Account | G4: 借方 | H4: 流动资产 | I4: 所有币别 | K4: 已审核
A5: 1002.01.01 | B5: 汇丰银行-741-282-503-838 | E5: 银行存款_【旭智资本】银行存款账户_汇丰银行-741-282-503-838 | F5: HSBC Account 741-282-503-838 | G5: 借方 | H5: 流动资产 | I5: 所有币别 | K5: 已审核
A6: 1002.01.01.01 | B6: 【旭智资本】汇丰港元储蓄账户 3838 | E6: 银行存款_【旭智资本】银行存款账户_汇丰银行-741-282-503-838_【旭智资本】汇丰港元储蓄账户 3838 | F6: ACPL HSBC HKD Savings | G6: 借方 | H6: 流动资产 | I6: 所有币别 | K6: 已审核
A7: 1002.01.01.02 | B7: 【旭智资本】汇丰港元往来账户 3838 | E7: 银行存款_【旭智资本】银行存款账户_汇丰银行-741-282-503-838_【旭智资本】汇丰港元往来账户 3838 | F7: ACPL HSBC HKD Current | G7: 借方 | H7: 流动资产 | I7: 所有币别 | K7: 已审核
A8: 1002.01.01.03 | B8: 【旭智资本】汇丰外币储蓄账户 - 人民币 3838 | E8: 银行存款_【旭智资本】银行存款账户_汇丰银行-741-282-503-838_【旭智资本】汇丰外币储蓄账户 - 人民币 3838 | F8: ACPL HSBC RMB Savings | G8: 借方 | H8: 流动资产 | I8: 所有币别 | K8: 已审核
A9: 1002.01.01.04 | B9: 【旭智资本】汇丰外币储蓄账户 - 美元 3838 | E9: 银行存款_【旭智资本】银行存款账户_汇丰银行-741-282-503-838_【旭智资本】汇丰外币储蓄账户 - 美元 3838 | F9: ACPL HSBC USD Savings | G9: 借方 | H9: 流动资产 | I9: 所有币别 | K9: 已审核
A10: 1002.01.01.05 | B10: 【旭智资本】汇丰港元定期存款 | E10: 银行存款_【旭智资本】银行存款账户_汇丰银行-741-282-503-838_【旭智资本】汇丰港元定期存款 | F10: ACPL HSBC HKD Time Deposit | G10: 借方 | H10: 流动资产 | I10: 所有币别 | K10: 已审核
A11: 1002.02 | B11: 【旭智资本（香港）】银行存款账户 | E11: 银行存款_【旭智资本（香港）】银行存款账户 | F11: ACPLHK Bank Account | G11: 借方 | H11: 流动资产 | I11: 所有币别 | K11: 已审核
A12: 1002.02.01 | B12: 汇丰银行-741-269492-838 | E12: 银行存款_【旭智资本（香港）】银行存款账户_汇丰银行-741-269492-838 | F12: HSBC Account 741-269492-838 | G12: 借方 | H12: 流动资产 | I12: 所有币别 | K12: 已审核
A13: 1002.02.01.01 | B13: 【旭智资本（香港）】汇丰港元储蓄账户 2838 | E13: 银行存款_【旭智资本（香港）】银行存款账户_汇丰银行-741-269492-838_【旭智资本（香港）】汇丰港元储蓄账户 2838 | F13: ACPLHK HSBC HKD Savings | G13: 借方 | H13: 流动资产 | I13: 所有币别 | K13: 已审核
A14: 1002.02.01.02 | B14: 【旭智资本（香港）】汇丰港元活期账户 2838 | E14: 银行存款_【旭智资本（香港）】银行存款账户_汇丰银行-741-269492-838_【旭智资本（香港）】汇丰港元活期账户 2838 | F14: ACPLHK HSBC HKD Current | G14: 借方 | H14: 流动资产 | I14: 所有币别 | K14: 已审核
... A76: 1002.31.03.01 | B76: 【郴州景叶新能源】三湘 人民币一般户 4937 | E76: 银行存款_【郴州景叶新能源】银行存款账户_三湘银行账户_【郴州景叶新能源】三湘 人民币一般户 4937 | F76: Chenzhou Jingye SXB RMB GDA 4937 | G76: 借方 | H76: 流动资产 | I76: 所有币别 | K76: 已审核
A77: 1002.31.04 | B77: 兴业银行账户 | E77: 银行存款_【郴州景叶新能源】银行存款账户_兴业银行账户 | F77: 0 | G77: 借方 | H77: 流动资产 | I77: 所有币别 | K77: 已审核
A78: 1002.31.04.01 | B78: 【郴州景叶新能源】兴业 人民监管户 9000 | E78: 银行存款_【郴州景叶新能源】银行存款账户_兴业银行账户_【郴州景叶新能源】兴业 人民监管户 9000 | F78: Chenzhou Jingye CIB RMB RA 9000 | G78: 借方 | H78: 流动资产 | I78: 所有币别 | K78: 已审核
A79: 1002.32 | B79: 【旭智富能（成都）】银行存款账户 | E79: 银行存款_【旭智富能（成都）】银行存款账户 | F79: Albamen Foxpower(Chengdu) Bank Account | G79: 借方 | H79: 流动资产 | I79: 所有币别 | K79: 已审核
A80: 1002.33 | B80: 【旭智富联（鹤壁）】银行存款账户 | E80: 银行存款_【旭智富联（鹤壁）】银行存款账户 | F80: Albamen Foxconn (Hebi) Bank Account | G80: 借方 | H80: 流动资产 | I80: 所有币别 | K80: 已审核
A81: 1012 | B81: 其他货币资金 | E81: 其他货币资金 | F81: Other Monetary Fund | G81: 借方 | H81: 流动资产 | K81: 已审核
A82: 1101 | B82: 交易性金融资产 | E82: 交易性金融资产 | F82: Financial Assets Held For Trading | G82: 借方 | H82: 流动资产 | K82: 已审核
A83: 1101.01 | B83: 投资成本 | E83: 交易性金融资产_投资成本 | F83: Investment Cost | G83: 借方 | H83: 流动资产 | K83: 已审核
A84: 1101.01.01 | B84: 基金 | E84: 交易性金融资产_投资成本_基金 | F84: Fund Investments | G84: 借方 | H84: 流动资产 | K84: 已审核
A85: 1101.01.02 | B85: 股权 | E85: 交易性金融资产_投资成本_股权 | F85: Equity Investments | G85: 借方 | H85: 流动资产 | K85: 已审核
A86: 1101.01.02.01 | B86: 宜兴旭智投资咨询合伙企业（有限合伙） | E86: 交易性金融资产_投资成本_股权_宜兴旭智投资咨询合伙企业（有限合伙） | F86: Yixing Albamen Investment Consultancy Limited Partnership | G86: 借方 | H86: 流动资产 | K86: 已审核
A87: 1101.01.02.02 | B87: 旭智富能新能源（深圳）有限责任公司 | E87: 交易性金融资产_投资成本_股权_旭智富能新能源（深圳）有限责任公司 | F87: Albamen Foxpower Renewable Energy (Shenzhen) Company Limited | G87: 借方 | H87: 流动资产 | K87: 已审核
A88: 1101.01.03 | B88: 银行理财 | E88: 交易性金融资产_投资成本_银行理财 | F88: Treasury Products | G88: 借方 | H88: 流动资产 | K88: 已审核
A89: 1101.02 | B89: 公允价值变动 | E89: 交易性金融资产_公允价值变动 | F89: Changes In Fair Value | G89: 借方 | H89: 流动资产 | K89: 已审核
A90: 1101.02.01 | B90: 基金 | E90: 交易性金融资产_公允价值变动_基金 | F90: Fund Investments | G90: 借方 | H90: 流动资产 | K90: 已审核
A91: 1101.02.02 | B91: 股权 | E91: 交易性金融资产_公允价值变动_股权 | F91: Equity Investments | G91: 借方 | H91: 流动资产 | K91: 已审核
A92: 1101.02.02.01 | B92: 宜兴旭智投资咨询合伙企业（有限合伙） | E92: 交易性金融资产_公允价值变动_股权_宜兴旭智投资咨询合伙企业（有限合伙） | F92: Yixing Albamen Investment Consultancy Limited Partnership | G92: 借方 | H92: 流动资产 | K92: 已审核
... A94: 1101.02.03 | B94: 银行理财 | E94: 交易性金融资产_公允价值变动_银行理财 | F94: Treasury Products | G94: 借方 | H94: 流动资产 | K94: 已审核
A95: 1121 | B95: 应收票据 | E95: 应收票据 | F95: Bills Receivables | G95: 借方 | H95: 流动资产 | I95: 所有币别 | J95: 客户 | K95: 已审核
A96: 1122 | B96: 应收账款 | E96: 应收账款 | F96: Accounts Receivables | G96: 借方 | H96: 流动资产 | I96: 所有币别 | J96: 客户 | K96: 已审核
A97: 1122.01 | B97: 咨询费收入 | E97: 应收账款_咨询费收入 | F97: Entities | G97: 借方 | H97: 流动资产 | I97: 所有币别 | J97: 客户 | K97: 已审核
A98: 1122.02 | B98: 管理费收入 | E98: 应收账款_管理费收入 | F98: Individual | G98: 借方 | H98: 流动资产 | I98: 所有币别 | J98: 客户 | K98: 已审核
A99: 1122.03 | B99: 售电收入 | E99: 应收账款_售电收入 | F99: Electricity Sales Revenue | G99: 借方 | H99: 流动资产 | J99: 客户 | K99: 已审核
A100: 1122.03.01 | B100: 暂估结算电费 | E100: 应收账款_售电收入_暂估结算电费 | F100: Estimated Electricity | G100: 借方 | H100: 流动资产 | J100: 客户 | K100: 已审核
A101: 1122.03.02 | B101: 实际结算电费 | E101: 应收账款_售电收入_实际结算电费 | F101: Actuai Electricity | G101: 借方 | H101: 流动资产 | J101: 客户 | K101: 已审核
A102: 1123 | B102: 预付账款 | E102: 预付账款 | F102: Prepayments | G102: 借方 | H102: 流动资产 | I102: 所有币别 | J102: 供应商 | K102: 已审核
...

Sheet 汇总
B2: 输入 - 情形1 | K2: 输入 - 情形2 | S2: 输入 - 情形3
C3: 年底 | D3: 46357 | L3: 年底 | M3: 46357 | T3: 年底 | U3: 46357
C4: RF's base (-)/+ | D4: -0.44861538 | L4: RF's base (-)/+ | M4: -0.44861538 | T4: RF's base (-)/+ | U4: -0.44861538
C5: RF's base in HKD | D5: ='[90]Personnel-HK 2026'!$U$11 -> 180700 | E5: =D5*12+1000000 -> 3168400 | L5: RF's base in HKD | M5: ='[90]Personnel-HK 2026'!$U$11 -> 180700 | N5: =M5*12+1000000 -> 3168400 | T5: RF's base in HKD | U5: 180700 | V5: 3168400
C6: 2026拟招聘员工： | D6: 月薪 | E6: 开始日期 | L6: 2026拟招聘员工： | M6: 月薪 | N6: 开始日期 | T6: 2026拟招聘员工： | U6: 月薪 | V6: 开始日期
C7: 风资源工程师 | D7: 35000 | E7: 46113 | G7: RMB | I7: 张弛 | L7: 风资源工程师 | M7: 35000 | N7: 46113 | P7: RMB | T7: 风资源工程师 | U7: 35000 | V7: 46113 | X7: RMB | Y7: RMB
C8: 电力交易员 | D8: 33000 | E8: 46054 | G8: RMB | I8: 贾璇 | L8: 电力交易员 | M8: 33000 | N8: 46054 | P8: RMB | T8: 电力交易员 | U8: 33000 | V8: 46054 | X8: RMB | Y8: RMB
C9: 律师 | D9: 60000 | E9: 46143 | G9: RMB | L9: 律师 | M9: 60000 | N9: 46143 | P9: RMB | T9: 律师 | U9: 60000 | V9: 46143 | X9: RMB | Y9: RMB
C10: 区域副总 | D10: 26000 | E10: 46143 | G10: RMB | L10: 区域副总 | M10: 26000 | N10: 46143 | P10: RMB | T10: 区域副总 | U10: 26000 | V10: 46143 | X10: RMB | Y10: RMB
C11: 项目会计 | D11: 17000 | E11: 46235 | G11: RMB | L11: 项目会计 | M11: 17000 | N11: 46235 | P11: RMB | T11: 项目会计 | U11: 17000 | V11: 46235 | X11: RMB | Y11: RMB
C12: 档案管理员 | D12: 12000 | E12: 46357 | G12: RMB | L12: 档案管理员 | M12: 12000 | N12: 46357 | P12: RMB | T12: 档案管理员 | U12: 12000 | V12: 46357 | X12: RMB | Y12: RMB
C13: RO HKD | D13: 60000 | E13: 46082 | G13: 开始日 | L13: RO HKD | M13: 60000 | N13: 46082 | P13: 开始日 | T13: RO HKD | U13: 60000 | V13: 46082 | X13: 开始日 | Y13: 开始日
C14: RO HKD | D14: 60000 | E14: 46569 | G14: 终止日 | I14: =61500*6*0.89 -> 328410 | L14: RO HKD | M14: 60000 | N14: 46569 | P14: 终止日 | T14: RO HKD | U14: 60000 | V14: 46569 | X14: 终止日 | Y14: 终止日
C15: Head of Origination | D15: 100000 | E15: 46143 | L15: Head of Origination | M15: 100000 | N15: 46143 | T15: Head of Origination | U15: 100000 | V15: 46143
C16: Op Partner - ZJX | D16: 80000 | E16: 46143 | L16: Op Partner - ZJX | M16: 80000 | N16: 46143 | T16: Op Partner - ZJX | U16: 80000 | V16: 46143
C17: 玉杰replacement | D17: 40000 | E17: 46388 | I17: 650000 | L17: 玉杰replacement | M17: 40000 | N17: 46388 | T17: 玉杰replacement | U17: 40000 | V17: 46388
C20: 2026拟终止员工： | D20: 月薪 | E20: 终止日期 | L20: 2026拟终止员工： | M20: 月薪 | N20: 终止日期 | T20: 2026拟终止员工： | U20: 月薪 | V20: 终止日期
C21: DQ | E21: 46387 | L21: DQ | N21: 46387 | T21: DQ | V21: 46387
C22: AC | E22: 46022 | L22: AC | N22: 46022 | T22: AC | V22: 46022
C25: 2026承担成本比例变化 | L25: 2026承担成本比例变化 | T25: 2026承担成本比例变化
C26: MG | D26: 0 | L26: MG | M26: 0 | T26: MG | U26: 0
C28: 员工奖金 | D28: 1 | E28: "1" Means has bonus, "0" means no | L28: 员工奖金 | M28: 1 | N28: "1" Means has bonus, "0" means no | T28: 员工奖金 | U28: 1 | V28: "1" Means has bonus, "0" means no
C29: 员工奖金总额 | D29: ='[90]Bonus 2026'!$J$19*D28 -> 2317250 | L29: 员工奖金总额 | M29: ='[90]Bonus 2026'!$J$19*M28 -> 2317250 | T29: 员工奖金总额 | U29: 2317250
C30: 员工加薪 | D30: 1 | E30: "1" Means has payrise, "0" means no | L30: 员工加薪 | M30: 1 | N30: "1" Means has payrise, "0" means no | T30: 员工加薪 | U30: 1 | V30: "1" Means has payrise, "0" means no
C31: 员工加薪总额 | D31: ='[90]Bonus 2026'!$J$31*D30 -> 714000 | L31: 员工加薪总额 | M31: ='[90]Bonus 2026'!$J$31*M30 -> 714000 | T31: 员工加薪总额 | U31: 714000
D32: 2026 | E32: 2027 | F32: 2028 | M32: 2026 | N32: 2027 | O32: 2028 | U32: 2026 | V32: 2027 | W32: 2028
C33: 富能基金总实缴金额 | D33: =情形1!S23 -> 79972.505 | E33: =情形1!AE23 -> 125842.73 | F33: =情形1!AQ23 -> 141939.41 | L33: 富能基金总实缴金额 | M33: =情形2!S23 -> 49941.559 | N33: =情形2!AE23 -> 95626.981 | O33: =情形2!AQ23 -> 141600.02 | T33: 富能基金总实缴金额 | U33: 27428.483 | V33: 72955.25 | W33: 118769.2
C34: 对应GP总实缴金额 | D34: =情形1!S33 -> 2665.7502 | E34: =情形1!AE33 -> 4194.7578 | F34: =情形1!AQ33 -> 4731.3137 | L34: 对应GP总实缴金额 | M34: =情形2!S33 -> 1664.7186 | N34: =情形2!AE33 -> 3187.566 | O34: =情形2!AQ33 -> 4720.0006 | T34: 对应GP总实缴金额 | U34: 1500 | V34: 2431.8417 | W34: 3958.9732
C35: 对应旭智总实缴金额 | D35: =情形1!S27+情形1!S29+情形1!S31 -> 2225.9014 | E35: =情形1!AE27+情形1!AE29+情形1!AE31 -> 3502.6228 | F35: =情形1!AQ27+情形1!AQ29+情形1!AQ31 -> 3950.647 | L35: 对应旭智总实缴金额 | M35: =情形2!S27+情形2!S29+情形2!S31 -> 1420.9167 | N35: =情形2!AE27+情形2!AE29+情形2!AE31 -> 2661.6176 | O35: =情形2!AQ27+情形2!AQ29+情形2!AQ31 -> 3941.2005 | T35: 对应旭智总实缴金额 | U35: 1347.0918 | V35: 2030.5878 | W35: 3305.7426
D36: =D35/(4900-750) -> 0.53636178 | E36: =E35/(4900-750) -> 0.84400549 | F36: =F35/(4900-750) -> 0.95196312 | M36: =M35/(4900-750) -> 0.34238956 | N36: =N35/(4900-750) -> 0.64135365 | O36: =O35/(4900-750) -> 0.94968687 | U36: 0.32460044 | V36: 0.48929827 | W36: 0.79656449
C38: 新增装机（MW) | L38: 新增装机（MW) | T38: 新增装机（MW)
C39: 46112 | D39: 0 | L39: 46112 | M39: 0 | T39: 46112 | U39: 0
C40: 46203 | D40: 100 | L40: 46203 | M40: 0 | T40: 46203 | U40: 0
C41: 46295 | D41: 0 | L41: 46295 | M41: =SUM(Pipeline!E5:E6)/2 -> 150 | T41: 46295 | U41: 150
C42: 46387 | D42: 400 | L42: 46387 | M42: 150 | T42: 46387 | U42: 0
C43: 2026平均累计装机 | D43: =INDEX(情形1!$9:$9,MATCH(汇总!$D$3,情形1!$3:$3,0)) -> 147.60274 | L43: 2026平均累计装机 | M43: =INDEX(情形2!$9:$9,MATCH(汇总!$D$3,情形2!$3:$3,0)) -> 117.87671 | T43: 2026平均累计装机 | U43: 105.13699
C44: 2026累计装机 | D44: =SUM(D38:D42)+55 -> 555 | L44: 2026累计装机 | M44: =SUM(M38:M42)+55 -> 355 | T44: 2026累计装机 | U44: 205
C45: 项目数量 | D45: =INDEX(情形1!$10:$10,MATCH(汇总!$D$3,情形1!$3:$3,0)) -> 5.7142857 | L45: 项目数量 | M45: =INDEX(情形2!$10:$10,MATCH(汇总!$D$3,情形2!$3:$3,0)) -> 5 | T45: 项目数量 | U45: 3
C46: 区域数量 | D46: =INDEX(情形1!$11:$11,MATCH(汇总!$D$3,情形1!$3:$3,0)) -> 2.8571429 | L46: 区域数量 | M46: =INDEX(情形2!$11:$11,MATCH(汇总!$D$3,情形2!$3:$3,0)) -> 3 | T46: 区域数量 | U46: 3
C47: 46477 | D47: 0 | L47: 46477 | M47: 50 | T47: 46477 | U47: 50 | Y47: 15000000
...

Sheet cashflow汇总实际
E1: ACPLHK | F1: ACPL | G1: ACPLSZ | H1: ACPLSZL | I1: ACPLGZ | J1: Yixing | K1: Total | M1: Albamen New Energy | N1: 深圳曦风 | O1: 深圳新融 | Q1: ACPLHK | R1: ACPL | S1: ACPLSZ | T1: ACPLSZL | U1: ACPLGZ | V1: Yixing | W1: Total
E2: RMB | F2: RMB | G2: RMB | H2: RMB | I2: RMB | J2: RMB | K2: RMB
B3: Cash balance | D3: 45866 | E3: =2765593+809735*0.91+46072*4.71 -> 3719451 | F3: =50223*0.91 -> 45702.93 | G3: 1757806 | H3: 5744218.3 | I3: 22134.7 | K3: =SUM(E3:I3) -> 11289313
B4: Transfer | E4: =-F4 -> -697963.14 | F4: =-F5 -> 697963.14 | K4: =SUM(E4:I4) -> 0
B5: Jul 2025 expenses | E5: -650484 | F5: -697963.14 | G5: -652247 | H5: -384285.96 | I5: -2321.86 | K5: =SUM(E5:I5) -> -2387302 | M5: +657k: ACPLSZ: 120k 鉴衡服务费; 普华22.5k咨询费；63k Q3深圳租金 ACPLHK: 82K IT服务; 62K 审计费； ACPL: 218k HK SPV费用; 90K 审计费
B6: Estimated Cash balance | D6: 45869 | E6: =SUM(E3:E5) -> 2371003.8 | F6: =SUM(F3:F5) -> 45702.93 | G6: =SUM(G3:G5) -> 1105559 | H6: =SUM(H3:H5) -> 5359932.3 | I6: =SUM(I3:I5) -> 19812.84 | K6: =SUM(K3:K5) -> 8902010.9
B8: Cash balance | D8: 45869 | E8: =2653612*0.91472 -> 2427312 | F8: =52344*0.91472 -> 47880.104 | G8: 1231689 | H8: 5444989 | I8: 49812.84 | K8: =SUM(E8:I8) -> 9201682.9
B9: Transfer | E9: =-F9 -> -360000 | F9: 360000 | K9: =SUM(E9:I9) -> 0
B10: injection | E10: =3600000*0.9 -> 3240000 | G10: =3600000*0.1 -> 360000 | K10: =SUM(E10:I10) -> 3600000
B11: Aug 2025 expenses | E11: =-香港!C213 -> -530274.16 | F11: =-香港!D213 -> -363985.38 | G11: =-'202601-202603（Forecast）'!#REF! -> #REF! | H11: =-'202601-202603（Forecast）'!#REF! -> #REF! | I11: =-'202601-202603（Forecast）'!#REF! -> #REF! | K11: =SUM(E11:I11) -> #REF! | M11: ACPLSZ: 普华22.5k咨询费 ACPLHK: 145K IT服务(license + cloud storage)
B12: Cash balance | D12: 45900 | E12: =SUM(E8:E11) -> 4777037.8 | F12: =SUM(F8:F11) -> 43894.721 | G12: =SUM(G8:G11) -> #REF! | H12: =SUM(H8:H11) -> #REF! | I12: =SUM(I8:I11) -> #REF! | K12: =SUM(K8:K11) -> #REF! | M12: *** ACPLHK will breach the liquid cap requirement after settlement of Aug expenses without capital injection
B14: Cash balance | D14: 45900 | E14: 4794239 | F14: 82455 | G14: 1111289 | H14: 5068590.2 | I14: 31863.6 | K14: =SUM(E14:I14) -> 11088437
B15: Transfer | E15: =-F15 -> -617625 | F15: =675000*0.915 -> 617625 | K15: =SUM(E15:I15) -> 0
B16: Sept 2025 expenses | E16: =-香港!C236 -> -499864.88 | F16: =-香港!D236+180000*0.915 -> -502745.06 | G16: =-'202601-202603（Forecast）'!#REF! -> #REF! | H16: =-'202601-202603（Forecast）'!O52 -> -766650.99 | I16: 0 | K16: =SUM(E16:I16) -> #REF!
B17: Cash balance | D17: 45930 | E17: =SUM(E14:E16) -> 3676749.1 | F17: =SUM(F14:F16) -> 197334.94 | G17: =SUM(G14:G16) -> #REF! | H17: =SUM(H14:H16) -> 4301939.2 | I17: =SUM(I14:I16) -> 31863.6 | K17: =SUM(K14:K16) -> #REF!
B18: Transfer | E18: =-F18 -> -502745.06 | F18: =-F20 -> 502745.06 | K18: =SUM(E18:I18) -> 0
B19: injection
B20: October 2025 expenses | E20: -520253 | F20: =F16 -> -502745.06 | G20: =-'202601-202603（Forecast）'!I52 -> -789872.76 | H20: =-'202601-202603（Forecast）'!P52 -> -344650.99 | I20: 0 | K20: =SUM(E20:I20) -> -2157521.8
B22: Cash balance | D22: 45961 | E22: =3251528*0.92 -> 2991405.8 | F22: =65292*0.92 -> 60068.64 | G22: =SUM('202601-202603（Forecast）'!I14,'202601-202603（Forecast）'!L14) -> 561081.68 | H22: ='202601-202603（Forecast）'!O14 -> 2694352.1 | I22: ='202601-202603（Forecast）'!F14 -> 86665.41 | K22: =SUM(E22:J22) -> 6393573.6
B23: Transfer | E23: =香港!C274*0.92 -> -368000 | F23: =-E23 -> 368000 | G23: =-H23 -> 450000 | H23: -450000 | I23: =-'202601-202603（Forecast）'!F52 -> -9982000 | K23: =SUM(E23:J23) -> -9982000
B24: November 2025 expenses | E24: =-香港!C272*0.92 -> -493674.76 | F24: =-香港!D272*0.92 -> -394737.96 | G24: -450000 | H24: -400000 | I24: 0 | K24: =SUM(E24:J24) -> -1738412.7
B25: Cash balance | D25: 45991 | E25: =SUM(E22:E24) -> 2129731 | F25: =SUM(F22:F24) -> 33330.68 | G25: =SUM(G22:G24) -> 561081.68 | H25: =SUM(H22:H24) -> 1844352.1 | I25: =SUM(I22:I24) -> -9895334.6 | K25: =SUM(K22:K24) -> -5326839.2
P26: Dec expense payments | R26: =-SUM(K35:K35) -> 1936677.9
B27: 实际现金余额 | D27: 45991 | E27: =2341169 -> 2341169 | F27: 46479 | G27: =104222.77+53825.34+17880.93 -> 175929.04 | H27: 3460729 | I27: 31951 | J27: 57445 | K27: =SUM(E27:J27) -> 6113702
B28: 利息收入 | E28: 3.34 | F28: 0.06 | G28: =5.68+3.33+2.26 -> 11.27 | H28: =3329.24+247.83+0.02 -> 3577.09 | I28: =41018+0.07+0.21+0.17+7.85 -> 41026.3 | J28: 7.26 | K28: =SUM(E28:J28) -> 44625.32
B29: 注资深圳曦和 | H29: -400000 | K29: =SUM(E29:J29) -> -400000 | P29: Dec non-routine items:
B30: IDG借款 | F30: =2000000*0.9 -> 1800000 | K30: =SUM(E30:J30) -> 1800000 | P30: IT cloud storage for 2025 | R30: =-香港!C286*0.92 -> -138000
B31: 现金分配 | G31: =-J31*10% -> 0 | I31: =-J31*0.9 -> 0 | K31: =SUM(E31:J31) -> 0 | P31: Huw 7-12 2025 service fee | R31: =-香港!C293*0.92 -> -276000
B32: 内部调拨 | K32: =SUM(E32:J32) -> 0 | P32: Cayman entity expenses | R32: =-SUM(香港!I283:I284)*7.1-香港!I293*7.1 -> -269912.25
B33: 减资款出境 | E33: =-I33 -> 0 | I33: =-SUM(I30:I32) -> 0 | K33: =SUM(E33:J33) -> 0 | P33: IDG Q1 service fee (Michael) | R33: =-'202601-202603（Forecast）'!I45 -> 0
B34: 内部调拨 | E34: =-F34 -> 647834.4 | F34: =-(800000-80000)*0.89977 -> -647834.4 | G34: 345000 | H34: -280000 | I34: -65000 | K34: =SUM(E34:J34) -> 0 | R34: =SUM(R30:R33) -> -683912.25
B35: 费用支出 | E35: =-395768.68 -> -395768.68 | F35: =-103720*0.9-637830.25 -> -731178.25 | G35: =-329240.35-105997.92 -> -435238.27 | H35: -374466.81 | I35: -0.9 | J35: -25 | K35: =SUM(E35:J35) -> -1936677.9 | P35: Dec routine expense payments | R35: =R26+R34 -> 1252765.7
B36: 现金余额 | D36: 46022 | E36: =SUM(E27:E35) -> 2593238.1 | F36: =SUM(F27:F35) -> 467466.41 | G36: =SUM(G27:G35) -> 85702.04 | H36: =SUM(H27:H35) -> 2409839.3 | I36: =SUM(I27:I35) -> 7976.4 | J36: =SUM(J27:J35) -> 57427.26 | K36: =SUM(K27:K35) -> 5621649.5
B37: 实际现金余额 | D37: 46022 | E37: 2574529 | F37: 466588 | G37: =G36 -> 85702.04 | H37: =H36 -> 2409839.3 | I37: =I36 -> 7976.4 | J37: =J36 -> 57427.26 | K37: =SUM(E37:J37) -> 5602062
B38: 曦和基金股转款 | D38: 46023 | I38: 10000000 | K38: =SUM(E38:J38) -> 10000000 | U38: 取得借款所收到的现金 | W38: 取得借款所收到的现金
B39: 内部调拨 | D39: 46023 | G39: 1540000 | I39: =-G39 -> -1540000 | K39: =SUM(E39:J39) -> 0 | Q39: =IF(E39>0,"收到的其他与筹资活动有关的现金","支付的其他与筹资活动有关的现金") -> 支付的其他与筹资活动有关的现金 | R39: =IF(F39>0,"收到的其他与筹资活动有关的现金","支付的其他与筹资活动有关的现金") -> 支付的其他与筹资活动有关的现金 | S39: =IF(G39>0,"收到的其他与筹资活动有关的现金","支付的其他与筹资活动有关的现金") -> 收到的其他与筹资活动有关的现金 | T39: =IF(H39>0,"收到的其他与筹资活动有关的现金","支付的其他与筹资活动有关的现金") -> 支付的其他与筹资活动有关的现金 | U39: =IF(I39>0,"收到的其他与筹资活动有关的现金","支付的其他与筹资活动有关的现金") -> 支付的其他与筹资活动有关的现金 | V39: =IF(J39>0,"收到的其他与筹资活动有关的现金","支付的其他与筹资活动有关的现金") -> 支付的其他与筹资活动有关的现金
B40: 注资深圳曦和 | D40: 46023 | H40: -400000 | K40: =SUM(E40:J40) -> -400000 | T40: 投资支付的现金 | W40: 投资支付的现金
B41: 注资宜兴旭智 | D41: 46023 | G41: -144000 | I41: -3516000 | J41: =-G41-I41 -> 3660000 | K41: =SUM(E41:J41) -> 0 | Q41: NA | S41: 投资支付的现金 | U41: 投资支付的现金 | V41: 吸收投资所收到的现金
B42: 内部调拨 | D42: 46023 | G42: =-H42 -> -780000 | H42: =500000+280000 -> 780000 | K42: =SUM(E42:J42) -> 0 | Q42: =IF(E42>0,"收到的其他与筹资活动有关的现金","支付的其他与筹资活动有关的现金") -> 支付的其他与筹资活动有关的现金 | R42: =IF(F42>0,"收到的其他与筹资活动有关的现金","支付的其他与筹资活动有关的现金") -> 支付的其他与筹资活动有关的现金 | S42: =IF(G42>0,"收到的其他与筹资活动有关的现金","支付的其他与筹资活动有关的现金") -> 支付的其他与筹资活动有关的现金 | T42: =IF(H42>0,"收到的其他与筹资活动有关的现金","支付的其他与筹资活动有关的现金") -> 收到的其他与筹资活动有关的现金 | U42: =IF(I42>0,"收到的其他与筹资活动有关的现金","支付的其他与筹资活动有关的现金") -> 支付的其他与筹资活动有关的现金 | V42: =IF(J42>0,"收到的其他与筹资活动有关的现金","支付的其他与筹资活动有关的现金") -> 支付的其他与筹资活动有关的现金
B43: 减资款出境 | D43: 46023 | E43: =-I43 -> 4924000 | I43: =-SUM(I38:I41)+20000 -> -4924000 | K43: =SUM(E43:J43) -> 0 | Q43: 收回投资所收到的现金 | U43: 支付的其他与筹资活动有关的现金
...

Sheet cashflow汇总预算2026
E1: ACPLHK | F1: ACPL | G1: ACPLSZ | H1: ACPLSZL | I1: ACPLGZ | J1: Yixing | K1: Total | M1: Albamen New Energy | N1: 深圳曦风 | O1: 深圳新融 | Q1: ACPLHK | R1: ACPL | S1: ACPLSZ | T1: ACPLSZL | U1: ACPLGZ | V1: Yixing | W1: Total
E2: RMB | F2: RMB | G2: RMB | H2: RMB | I2: RMB | J2: RMB | K2: RMB
B3: Cash balance | D3: 45866 | E3: =2765593+809735*0.91+46072*4.71 -> 3719451 | F3: =50223*0.91 -> 45702.93 | G3: 1757806 | H3: 5744218.3 | I3: 22134.7 | K3: =SUM(E3:I3) -> 11289313
B4: Transfer | E4: =-F4 -> -697963.14 | F4: =-F5 -> 697963.14 | K4: =SUM(E4:I4) -> 0
B5: Jul 2025 expenses | E5: -650484 | F5: -697963.14 | G5: -652247 | H5: -384285.96 | I5: -2321.86 | K5: =SUM(E5:I5) -> -2387302 | M5: +657k: ACPLSZ: 120k 鉴衡服务费; 普华22.5k咨询费；63k Q3深圳租金 ACPLHK: 82K IT服务; 62K 审计费； ACPL: 218k HK SPV费用; 90K 审计费
B6: Estimated Cash balance | D6: 45869 | E6: =SUM(E3:E5) -> 2371003.8 | F6: =SUM(F3:F5) -> 45702.93 | G6: =SUM(G3:G5) -> 1105559 | H6: =SUM(H3:H5) -> 5359932.3 | I6: =SUM(I3:I5) -> 19812.84 | K6: =SUM(K3:K5) -> 8902010.9
B8: Cash balance | D8: 45869 | E8: =2653612*0.91472 -> 2427312 | F8: =52344*0.91472 -> 47880.104 | G8: 1231689 | H8: 5444989 | I8: 49812.84 | K8: =SUM(E8:I8) -> 9201682.9
B9: Transfer | E9: =-F9 -> -360000 | F9: 360000 | K9: =SUM(E9:I9) -> 0
B10: injection | E10: =3600000*0.9 -> 3240000 | G10: =3600000*0.1 -> 360000 | K10: =SUM(E10:I10) -> 3600000
B11: Aug 2025 expenses | E11: =-香港!C213 -> -530274.16 | F11: =-香港!D213 -> -363985.38 | G11: =-'202601-202603（Forecast）'!#REF! -> #REF! | H11: =-'202601-202603（Forecast）'!#REF! -> #REF! | I11: =-'202601-202603（Forecast）'!#REF! -> #REF! | K11: =SUM(E11:I11) -> #REF! | M11: ACPLSZ: 普华22.5k咨询费 ACPLHK: 145K IT服务(license + cloud storage)
B12: Cash balance | D12: 45900 | E12: =SUM(E8:E11) -> 4777037.8 | F12: =SUM(F8:F11) -> 43894.721 | G12: =SUM(G8:G11) -> #REF! | H12: =SUM(H8:H11) -> #REF! | I12: =SUM(I8:I11) -> #REF! | K12: =SUM(K8:K11) -> #REF! | M12: *** ACPLHK will breach the liquid cap requirement after settlement of Aug expenses without capital injection
B14: Cash balance | D14: 45900 | E14: 4794239 | F14: 82455 | G14: 1111289 | H14: 5068590.2 | I14: 31863.6 | K14: =SUM(E14:I14) -> 11088437
B15: Transfer | E15: =-F15 -> -617625 | F15: =675000*0.915 -> 617625 | K15: =SUM(E15:I15) -> 0
B16: Sept 2025 expenses | E16: =-香港!C236 -> -499864.88 | F16: =-香港!D236+180000*0.915 -> -502745.06 | G16: =-'202601-202603（Forecast）'!#REF! -> #REF! | H16: =-'202601-202603（Forecast）'!O52 -> -766650.99 | I16: 0 | K16: =SUM(E16:I16) -> #REF!
B17: Cash balance | D17: 45930 | E17: =SUM(E14:E16) -> 3676749.1 | F17: =SUM(F14:F16) -> 197334.94 | G17: =SUM(G14:G16) -> #REF! | H17: =SUM(H14:H16) -> 4301939.2 | I17: =SUM(I14:I16) -> 31863.6 | K17: =SUM(K14:K16) -> #REF!
B18: Transfer | E18: =-F18 -> -502745.06 | F18: =-F20 -> 502745.06 | K18: =SUM(E18:I18) -> 0
B19: injection
B20: October 2025 expenses | E20: -520253 | F20: =F16 -> -502745.06 | G20: =-'202601-202603（Forecast）'!I52 -> -789872.76 | H20: =-'202601-202603（Forecast）'!P52 -> -344650.99 | I20: 0 | K20: =SUM(E20:I20) -> -2157521.8
B22: Cash balance | D22: 45961 | E22: =3251528*0.92 -> 2991405.8 | F22: =65292*0.92 -> 60068.64 | G22: =SUM('202601-202603（Forecast）'!I14,'202601-202603（Forecast）'!L14) -> 561081.68 | H22: ='202601-202603（Forecast）'!O14 -> 2694352.1 | I22: ='202601-202603（Forecast）'!F14 -> 86665.41 | K22: =SUM(E22:J22) -> 6393573.6
B23: Transfer | E23: =香港!C274*0.92 -> -368000 | F23: =-E23 -> 368000 | G23: =-H23 -> 450000 | H23: -450000 | I23: =-'202601-202603（Forecast）'!F52 -> -9982000 | K23: =SUM(E23:J23) -> -9982000
B24: November 2025 expenses | E24: =-香港!C272*0.92 -> -493674.76 | F24: =-香港!D272*0.92 -> -394737.96 | G24: -450000 | H24: -400000 | I24: 0 | K24: =SUM(E24:J24) -> -1738412.7
B25: Cash balance | D25: 45991 | E25: =SUM(E22:E24) -> 2129731 | F25: =SUM(F22:F24) -> 33330.68 | G25: =SUM(G22:G24) -> 561081.68 | H25: =SUM(H22:H24) -> 1844352.1 | I25: =SUM(I22:I24) -> -9895334.6 | K25: =SUM(K22:K24) -> -5326839.2
P26: Dec expense payments | R26: =-SUM(K35:K35) -> 1936677.9
B27: 实际现金余额 | D27: 45991 | E27: =2341169 -> 2341169 | F27: 46479 | G27: =104222.77+53825.34+17880.93 -> 175929.04 | H27: 3460729 | I27: 31951 | J27: 57445 | K27: =SUM(E27:J27) -> 6113702
B28: 利息收入 | E28: 3.34 | F28: 0.06 | G28: =5.68+3.33+2.26 -> 11.27 | H28: =3329.24+247.83+0.02 -> 3577.09 | I28: =41018+0.07+0.21+0.17+7.85 -> 41026.3 | J28: 7.26 | K28: =SUM(E28:J28) -> 44625.32
B29: 注资深圳曦和 | H29: -400000 | K29: =SUM(E29:J29) -> -400000 | P29: Dec non-routine items:
B30: IDG借款 | F30: =2000000*0.9 -> 1800000 | K30: =SUM(E30:J30) -> 1800000 | P30: IT cloud storage for 2025 | R30: =-香港!C286*0.92 -> -138000
B31: 现金分配 | G31: =-J31*10% -> 0 | I31: =-J31*0.9 -> 0 | K31: =SUM(E31:J31) -> 0 | P31: Huw 7-12 2025 service fee | R31: =-香港!C293*0.92 -> -276000
B32: 内部调拨 | K32: =SUM(E32:J32) -> 0 | P32: Cayman entity expenses | R32: =-SUM(香港!I283:I284)*7.1-香港!I293*7.1 -> -269912.25
B33: 减资款出境 | E33: =-I33 -> 0 | I33: =-SUM(I30:I32) -> 0 | K33: =SUM(E33:J33) -> 0 | P33: IDG Q1 service fee (Michael) | R33: =-'202601-202603（Forecast）'!I45 -> 0
B34: 内部调拨 | E34: =-F34 -> 647834.4 | F34: =-(800000-80000)*0.89977 -> -647834.4 | G34: 345000 | H34: -280000 | I34: -65000 | K34: =SUM(E34:J34) -> 0 | R34: =SUM(R30:R33) -> -683912.25
B35: 费用支出 | E35: =-395768.68 -> -395768.68 | F35: =-103720*0.9-637830.25 -> -731178.25 | G35: =-329240.35-105997.92 -> -435238.27 | H35: -374466.81 | I35: -0.9 | J35: -25 | K35: =SUM(E35:J35) -> -1936677.9 | P35: Dec routine expense payments | R35: =R26+R34 -> 1252765.7
B36: 现金余额 | D36: 46022 | E36: =SUM(E27:E35) -> 2593238.1 | F36: =SUM(F27:F35) -> 467466.41 | G36: =SUM(G27:G35) -> 85702.04 | H36: =SUM(H27:H35) -> 2409839.3 | I36: =SUM(I27:I35) -> 7976.4 | J36: =SUM(J27:J35) -> 57427.26 | K36: =SUM(K27:K35) -> 5621649.5
B37: 实际现金余额 | D37: 46022 | E37: 2574529 | F37: 466588 | G37: =G36 -> 85702.04 | H37: =H36 -> 2409839.3 | I37: =I36 -> 7976.4 | J37: =J36 -> 57427.26 | K37: =SUM(E37:J37) -> 5602062
B38: 曦和基金股转款 | D38: 46023 | I38: 10000000 | K38: =SUM(E38:J38) -> 10000000 | U38: 取得借款所收到的现金 | W38: 取得借款所收到的现金
B39: 内部调拨 | D39: 46023 | G39: 1540000 | I39: =-G39 -> -1540000 | K39: =SUM(E39:J39) -> 0 | Q39: =IF(E39>0,"收到的其他与筹资活动有关的现金","支付的其他与筹资活动有关的现金") -> 支付的其他与筹资活动有关的现金 | R39: =IF(F39>0,"收到的其他与筹资活动有关的现金","支付的其他与筹资活动有关的现金") -> 支付的其他与筹资活动有关的现金 | S39: =IF(G39>0,"收到的其他与筹资活动有关的现金","支付的其他与筹资活动有关的现金") -> 收到的其他与筹资活动有关的现金 | T39: =IF(H39>0,"收到的其他与筹资活动有关的现金","支付的其他与筹资活动有关的现金") -> 支付的其他与筹资活动有关的现金 | U39: =IF(I39>0,"收到的其他与筹资活动有关的现金","支付的其他与筹资活动有关的现金") -> 支付的其他与筹资活动有关的现金 | V39: =IF(J39>0,"收到的其他与筹资活动有关的现金","支付的其他与筹资活动有关的现金") -> 支付的其他与筹资活动有关的现金
B40: 注资深圳曦和 | D40: 46023 | H40: -400000 | K40: =SUM(E40:J40) -> -400000 | T40: 投资支付的现金 | W40: 投资支付的现金
B41: 注资宜兴旭智 | D41: 46023 | G41: -144000 | I41: -3516000 | J41: =-G41-I41 -> 3660000 | K41: =SUM(E41:J41) -> 0 | Q41: NA | S41: 投资支付的现金 | U41: 投资支付的现金 | V41: 吸收投资所收到的现金
B42: 内部调拨 | D42: 46023 | G42: =-H42 -> -780000 | H42: =500000+280000 -> 780000 | K42: =SUM(E42:J42) -> 0 | Q42: =IF(E42>0,"收到的其他与筹资活动有关的现金","支付的其他与筹资活动有关的现金") -> 支付的其他与筹资活动有关的现金 | R42: =IF(F42>0,"收到的其他与筹资活动有关的现金","支付的其他与筹资活动有关的现金") -> 支付的其他与筹资活动有关的现金 | S42: =IF(G42>0,"收到的其他与筹资活动有关的现金","支付的其他与筹资活动有关的现金") -> 支付的其他与筹资活动有关的现金 | T42: =IF(H42>0,"收到的其他与筹资活动有关的现金","支付的其他与筹资活动有关的现金") -> 收到的其他与筹资活动有关的现金 | U42: =IF(I42>0,"收到的其他与筹资活动有关的现金","支付的其他与筹资活动有关的现金") -> 支付的其他与筹资活动有关的现金 | V42: =IF(J42>0,"收到的其他与筹资活动有关的现金","支付的其他与筹资活动有关的现金") -> 支付的其他与筹资活动有关的现金
B43: 减资款出境 | D43: 46023 | E43: =-I43 -> 4924000 | I43: =-SUM(I38:I41)+20000 -> -4924000 | K43: =SUM(E43:J43) -> 0 | Q43: 收回投资所收到的现金 | U43: 支付的其他与筹资活动有关的现金
...

Sheet cashflow汇总预算 2027
B1: 0.05 | E1: ACPLHK | F1: ACPL | G1: ACPLSZ | H1: ACPLSZL | I1: ACPLGZ | J1: Yixing | K1: Total | M1: Albamen New Energy | N1: 深圳曦风 | O1: 深圳新融 | Q1: ACPLHK | R1: ACPL | S1: ACPLSZ | T1: ACPLSZL | U1: ACPLGZ | V1: Yixing | W1: Total
E2: RMB | F2: RMB | G2: RMB | H2: RMB | I2: RMB | J2: RMB | K2: RMB
B3: Cash balance | D3: 45866 | E3: =2765593+809735*0.91+46072*4.71 -> 3719451 | F3: =50223*0.91 -> 45702.93 | G3: 1757806 | H3: 5744218.3 | I3: 22134.7 | K3: =SUM(E3:I3) -> 11289313
B4: Transfer | E4: =-F4 -> -697963.14 | F4: =-F5 -> 697963.14 | K4: =SUM(E4:I4) -> 0
B5: Jul 2025 expenses | E5: -650484 | F5: -697963.14 | G5: -652247 | H5: -384285.96 | I5: -2321.86 | K5: =SUM(E5:I5) -> -2387302 | M5: +657k: ACPLSZ: 120k 鉴衡服务费; 普华22.5k咨询费；63k Q3深圳租金 ACPLHK: 82K IT服务; 62K 审计费； ACPL: 218k HK SPV费用; 90K 审计费
B6: Estimated Cash balance | D6: 45869 | E6: =SUM(E3:E5) -> 2371003.8 | F6: =SUM(F3:F5) -> 45702.93 | G6: =SUM(G3:G5) -> 1105559 | H6: =SUM(H3:H5) -> 5359932.3 | I6: =SUM(I3:I5) -> 19812.84 | K6: =SUM(K3:K5) -> 8902010.9
B8: Cash balance | D8: 45869 | E8: =2653612*0.91472 -> 2427312 | F8: =52344*0.91472 -> 47880.104 | G8: 1231689 | H8: 5444989 | I8: 49812.84 | K8: =SUM(E8:I8) -> 9201682.9
B9: Transfer | E9: =-F9 -> -360000 | F9: 360000 | K9: =SUM(E9:I9) -> 0
B10: injection | E10: =3600000*0.9 -> 3240000 | G10: =3600000*0.1 -> 360000 | K10: =SUM(E10:I10) -> 3600000
B11: Aug 2025 expenses | E11: =-香港!C213 -> -530274.16 | F11: =-香港!D213 -> -363985.38 | G11: =-'202601-202603（Forecast）'!#REF! -> #REF! | H11: =-'202601-202603（Forecast）'!#REF! -> #REF! | I11: =-'202601-202603（Forecast）'!#REF! -> #REF! | K11: =SUM(E11:I11) -> #REF! | M11: ACPLSZ: 普华22.5k咨询费 ACPLHK: 145K IT服务(license + cloud storage)
B12: Cash balance | D12: 45900 | E12: =SUM(E8:E11) -> 4777037.8 | F12: =SUM(F8:F11) -> 43894.721 | G12: =SUM(G8:G11) -> #REF! | H12: =SUM(H8:H11) -> #REF! | I12: =SUM(I8:I11) -> #REF! | K12: =SUM(K8:K11) -> #REF! | M12: *** ACPLHK will breach the liquid cap requirement after settlement of Aug expenses without capital injection
B14: Cash balance | D14: 45900 | E14: 4794239 | F14: 82455 | G14: 1111289 | H14: 5068590.2 | I14: 31863.6 | K14: =SUM(E14:I14) -> 11088437
B15: Transfer | E15: =-F15 -> -617625 | F15: =675000*0.915 -> 617625 | K15: =SUM(E15:I15) -> 0
B16: Sept 2025 expenses | E16: =-香港!C236 -> -499864.88 | F16: =-香港!D236+180000*0.915 -> -502745.06 | G16: =-'202601-202603（Forecast）'!#REF! -> #REF! | H16: =-'202601-202603（Forecast）'!O52 -> -766650.99 | I16: 0 | K16: =SUM(E16:I16) -> #REF!
B17: Cash balance | D17: 45930 | E17: =SUM(E14:E16) -> 3676749.1 | F17: =SUM(F14:F16) -> 197334.94 | G17: =SUM(G14:G16) -> #REF! | H17: =SUM(H14:H16) -> 4301939.2 | I17: =SUM(I14:I16) -> 31863.6 | K17: =SUM(K14:K16) -> #REF!
B18: Transfer | E18: =-F18 -> -502745.06 | F18: =-F20 -> 502745.06 | K18: =SUM(E18:I18) -> 0
B19: injection
B20: October 2025 expenses | E20: -520253 | F20: =F16 -> -502745.06 | G20: =-'202601-202603（Forecast）'!I52 -> -789872.76 | H20: =-'202601-202603（Forecast）'!P52 -> -344650.99 | I20: 0 | K20: =SUM(E20:I20) -> -2157521.8
B22: Cash balance | D22: 45961 | E22: =3251528*0.92 -> 2991405.8 | F22: =65292*0.92 -> 60068.64 | G22: =SUM('202601-202603（Forecast）'!I14,'202601-202603（Forecast）'!L14) -> 561081.68 | H22: ='202601-202603（Forecast）'!O14 -> 2694352.1 | I22: ='202601-202603（Forecast）'!F14 -> 86665.41 | K22: =SUM(E22:J22) -> 6393573.6
B23: Transfer | E23: =香港!C274*0.92 -> -368000 | F23: =-E23 -> 368000 | G23: =-H23 -> 450000 | H23: -450000 | I23: =-'202601-202603（Forecast）'!F52 -> -9982000 | K23: =SUM(E23:J23) -> -9982000
B24: November 2025 expenses | E24: =-香港!C272*0.92 -> -493674.76 | F24: =-香港!D272*0.92 -> -394737.96 | G24: -450000 | H24: -400000 | I24: 0 | K24: =SUM(E24:J24) -> -1738412.7
B25: Cash balance | D25: 45991 | E25: =SUM(E22:E24) -> 2129731 | F25: =SUM(F22:F24) -> 33330.68 | G25: =SUM(G22:G24) -> 561081.68 | H25: =SUM(H22:H24) -> 1844352.1 | I25: =SUM(I22:I24) -> -9895334.6 | K25: =SUM(K22:K24) -> -5326839.2
P26: Dec expense payments | R26: =-SUM(K35:K35) -> 1936677.9
B27: 实际现金余额 | D27: 45991 | E27: =2341169 -> 2341169 | F27: 46479 | G27: =104222.77+53825.34+17880.93 -> 175929.04 | H27: 3460729 | I27: 31951 | J27: 57445 | K27: =SUM(E27:J27) -> 6113702
B28: 利息收入 | E28: 3.34 | F28: 0.06 | G28: =5.68+3.33+2.26 -> 11.27 | H28: =3329.24+247.83+0.02 -> 3577.09 | I28: =41018+0.07+0.21+0.17+7.85 -> 41026.3 | J28: 7.26 | K28: =SUM(E28:J28) -> 44625.32
B29: 注资深圳曦和 | H29: -400000 | K29: =SUM(E29:J29) -> -400000 | P29: Dec non-routine items:
B30: IDG借款 | F30: =2000000*0.9 -> 1800000 | K30: =SUM(E30:J30) -> 1800000 | P30: IT cloud storage for 2025 | R30: =-香港!C286*0.92 -> -138000
B31: 现金分配 | G31: =-J31*10% -> 0 | I31: =-J31*0.9 -> 0 | K31: =SUM(E31:J31) -> 0 | P31: Huw 7-12 2025 service fee | R31: =-香港!C293*0.92 -> -276000
B32: 内部调拨 | K32: =SUM(E32:J32) -> 0 | P32: Cayman entity expenses | R32: =-SUM(香港!I283:I284)*7.1-香港!I293*7.1 -> -269912.25
B33: 减资款出境 | E33: =-I33 -> 0 | I33: =-SUM(I30:I32) -> 0 | K33: =SUM(E33:J33) -> 0 | P33: IDG Q1 service fee (Michael) | R33: =-'202601-202603（Forecast）'!I45 -> 0
B34: 内部调拨 | E34: =-F34 -> 647834.4 | F34: =-(800000-80000)*0.89977 -> -647834.4 | G34: 345000 | H34: -280000 | I34: -65000 | K34: =SUM(E34:J34) -> 0 | R34: =SUM(R30:R33) -> -683912.25
B35: 费用支出 | E35: =-395768.68 -> -395768.68 | F35: =-103720*0.9-637830.25 -> -731178.25 | G35: =-329240.35-105997.92 -> -435238.27 | H35: -374466.81 | I35: -0.9 | J35: -25 | K35: =SUM(E35:J35) -> -1936677.9 | P35: Dec routine expense payments | R35: =R26+R34 -> 1252765.7
B36: 现金余额 | D36: 46022 | E36: =SUM(E27:E35) -> 2593238.1 | F36: =SUM(F27:F35) -> 467466.41 | G36: =SUM(G27:G35) -> 85702.04 | H36: =SUM(H27:H35) -> 2409839.3 | I36: =SUM(I27:I35) -> 7976.4 | J36: =SUM(J27:J35) -> 57427.26 | K36: =SUM(K27:K35) -> 5621649.5
B37: 现金余额 | D37: 46387 | E37: =cashflow汇总预算2026!E146 -> 2520994.5 | F37: =cashflow汇总预算2026!F146 -> 6860650.6 | G37: =cashflow汇总预算2026!G146 -> 2783341.9 | H37: =cashflow汇总预算2026!H146 -> 930638.48 | I37: =cashflow汇总预算2026!I146 -> 168881.4 | J37: =cashflow汇总预算2026!J146 -> 47146.213 | K37: =cashflow汇总预算2026!K146 -> 13311653 | M37: =cashflow汇总预算2026!M146 -> 0 | N37: =cashflow汇总预算2026!N146 -> 133287.51 | O37: =cashflow汇总预算2026!O146 -> 266849.96
B38: 注资Albamen New Energy | D38: 46388 | F38: =-INDEX(情形1!$26:$26,MATCH($D38,情形1!$3:$3))*10000 -> -114668.91 | K38: =SUM(E38:J38) -> -114668.91 | M38: =-F38/75% -> 152891.88 | R38: 投资支付的现金 | W38: =R38 -> 投资支付的现金
B39: 注资深圳曦风 | D39: 46388 | H39: =-INDEX(情形1!$30:$30,MATCH($D39,情形1!$3:$3))*10000 -> -34400.672 | K39: =SUM(E39:J39) -> -34400.672 | M39: =H39/900*4000 -> -152891.88 | N39: =-H39-M39 -> 187292.55 | T39: 投资支付的现金 | W39: 投资支付的现金
B40: 注资深圳新融 | D40: 46388 | G40: =-INDEX(情形1!$28:$28,MATCH($D40,情形1!$3:$3))*10000 -> -63704.949 | K40: =SUM(E40:J40) -> -63704.949 | N40: =G40/1250*3650 -> -186018.45 | O40: =-G40-N40 -> 249723.4 | Q40: 投资支付的现金 | W40: 投资支付的现金
B41: 注资JV基金 | D41: 46388 | K41: =SUM(E41:J41) -> 0 | O41: =-INDEX(情形1!$32:$32,MATCH($D41,情形1!$3:$3))*10000 -> -254819.8
B42: 内部调拨 | D42: 46388 | E42: =-F42 -> -554355.86 | F42: =-F43 -> 554355.86 | G42: 1500000 | H42: =-G42 -> -1500000 | K42: =SUM(E42:J42) -> 0 | Q42: =IF(E42>0,"收到的其他与筹资活动有关的现金","支付的其他与筹资活动有关的现金") -> 支付的其他与筹资活动有关的现金 | R42: =IF(F42>0,"收到的其他与筹资活动有关的现金","支付的其他与筹资活动有关的现金") -> 收到的其他与筹资活动有关的现金 | S42: =IF(G42>0,"收到的其他与筹资活动有关的现金","支付的其他与筹资活动有关的现金") -> 收到的其他与筹资活动有关的现金 | T42: =IF(H42>0,"收到的其他与筹资活动有关的现金","支付的其他与筹资活动有关的现金") -> 支付的其他与筹资活动有关的现金 | U42: =IF(I42>0,"收到的其他与筹资活动有关的现金","支付的其他与筹资活动有关的现金") -> 支付的其他与筹资活动有关的现金 | V42: =IF(J42>0,"收到的其他与筹资活动有关的现金","支付的其他与筹资活动有关的现金") -> 支付的其他与筹资活动有关的现金
B43: 费用支出 | D43: 46388 | E43: =cashflow汇总预算2026!E47*(1+'cashflow汇总预算 2027'!$B$1) -> -752396.29 | F43: =cashflow汇总预算2026!F47*(1+'cashflow汇总预算 2027'!$B$1) -> -554355.86 | G43: =cashflow汇总预算2026!G47*(1+'cashflow汇总预算 2027'!$B$1) -> -762658.98 | H43: =cashflow汇总预算2026!H47*(1+'cashflow汇总预算 2027'!$B$1) -> -445341.52 | I43: =cashflow汇总预算2026!I47*(1+'cashflow汇总预算 2027'!$B$1) -> -2100 | J43: =cashflow汇总预算2026!J47*(1+'cashflow汇总预算 2027'!$B$1) -> 0 | K43: =SUM(E43:J43) -> -2516852.6
...

Sheet 情形1
C2: 1 | D2: 2 | F2: 3 | G2: 18 | H2: 19 | I2: 20 | J2: 21 | K2: 22 | L2: 23 | M2: 24 | N2: 25 | O2: 26 | P2: 27 | Q2: 28 | R2: 29 | S2: 30 | T2: 31 | U2: 32 | V2: 33 | W2: 34 | X2: 35 | Y2: 36 | Z2: 37 | AA2: 38 | AB2: 39 | AC2: 40 | AD2: 41 | AE2: 42 | AF2: 43 | AG2: 44 | AH2: 45 | AI2: 46 | AJ2: 47 | AK2: 48
A3: 1 | G3: 45992 | H3: 46023 | I3: 46054 | J3: 46082 | K3: 46113 | L3: 46143 | M3: 46174 | N3: 46204 | O3: 46235 | P3: 46266 | Q3: 46296 | R3: 46327 | S3: 46357 | T3: 46388 | U3: 46419 | V3: 46447 | W3: 46478 | X3: 46508 | Y3: 46539 | Z3: 46569 | AA3: 46600 | AB3: 46631 | AC3: 46661 | AD3: 46692 | AE3: 46722 | AF3: 46753 | AG3: 46784 | AH3: 46813 | AI3: 46844 | AJ3: 46874 | AK3: 46905 | AL3: 46935 | AM3: 46966 | AN3: 46997 | AO3: 47027 | AP3: 47058 | AQ3: 47088 | AR3: 47119 | AS3: 47150 | AT3: 47178 | AU3: 47209 | AV3: 47239 | AW3: 47270 | AX3: 47300 | AY3: 47331 | AZ3: 47362 | BA3: 47392 | BB3: 47423 | BC3: 47453 | BD3: 47484 | BE3: 47515 | BF3: 47543 | BG3: 47574 | BH3: 47604 | BI3: 47635 | BJ3: 47665 | BK3: 47696 | BL3: 47727 | BM3: 47757 | BN3: 47788 | BO3: 47818
C4: MAA季度管理费支付期间 | H4: 1 | I4: 0 | J4: 0 | K4: 1 | L4: 0 | M4: 0 | N4: 1 | O4: 0 | P4: 0 | Q4: 1 | R4: 0 | S4: 0 | T4: 1 | U4: 0 | V4: 0 | W4: 1 | X4: 0 | Y4: 0 | Z4: 1 | AA4: 0 | AB4: 0 | AC4: 1 | AD4: 0 | AE4: 0 | AF4: 1 | AG4: 0 | AH4: 0 | AI4: 1 | AJ4: 0 | AK4: 0 | AL4: 1 | AM4: 0 | AN4: 0 | AO4: 1 | AP4: 0 | AQ4: 0 | AR4: 1 | AS4: 0 | AT4: 0 | AU4: 1 | AV4: 0 | AW4: 0 | AX4: 1 | AY4: 0 | AZ4: 0 | BA4: 1 | BB4: 0 | BC4: 0 | BD4: 1 | BE4: 0 | BF4: 0 | BG4: 1 | BH4: 0 | BI4: 0 | BJ4: 1 | BK4: 0 | BL4: 0 | BM4: 1 | BN4: 0 | BO4: 0 | BP4: 1 | BQ4: 0 | BR4: 0 | BS4: 1 | BT4: 0 | BU4: 0
A5: 2 | C5: MAA新增资本管理费支付期间 | H5: 0 | I5: 1 | J5: 1 | K5: 0 | L5: 1 | M5: 1 | N5: 0 | O5: 1 | P5: 1 | Q5: 0 | R5: 1 | S5: 1 | T5: 0 | U5: 1 | V5: 1 | W5: 0 | X5: 1 | Y5: 1 | Z5: 0 | AA5: 1 | AB5: 1 | AC5: 0 | AD5: 1 | AE5: 1 | AF5: 0 | AG5: 1 | AH5: 1 | AI5: 0 | AJ5: 1 | AK5: 1 | AL5: 0 | AM5: 1 | AN5: 1 | AO5: 0 | AP5: 1 | AQ5: 1 | AR5: 0 | AS5: 1 | AT5: 1 | AU5: 0 | AV5: 1 | AW5: 1 | AX5: 0 | AY5: 1 | AZ5: 1 | BA5: 0 | BB5: 1 | BC5: 1 | BD5: 0 | BE5: 1 | BF5: 1 | BG5: 0 | BH5: 1 | BI5: 1 | BJ5: 0 | BK5: 1 | BL5: 1 | BM5: 0 | BN5: 1 | BO5: 1 | BP5: 0 | BQ5: 1 | BR5: 1 | BS5: 0 | BT5: 1 | BU5: 1
C6: 天数 | H6: =DAY(EOMONTH(H3,0)) -> 31 | I6: =DAY(EOMONTH(I3,0)) -> 28 | J6: =DAY(EOMONTH(J3,0)) -> 31 | K6: =DAY(EOMONTH(K3,0)) -> 30 | L6: =DAY(EOMONTH(L3,0)) -> 31 | M6: =DAY(EOMONTH(M3,0)) -> 30 | N6: =DAY(EOMONTH(N3,0)) -> 31 | O6: =DAY(EOMONTH(O3,0)) -> 31 | ... AJ6: =DAY(EOMONTH(AJ3,0)) -> 31 | AK6: =DAY(EOMONTH(AP3,0)) -> 30 | AL6: =DAY(EOMONTH(AL3,0)) -> 31 | AM6: =DAY(EOMONTH(AM3,0)) -> 31 | AN6: =DAY(EOMONTH(AN3,0)) -> 30 | AO6: =DAY(EOMONTH(AO3,0)) -> 31 | AP6: =DAY(EOMONTH(AP3,0)) -> 30 | AQ6: =DAY(EOMONTH(AQ3,0)) -> 31 | AR6: =DAY(EOMONTH(AR3,0)) -> 31 | AS6: =DAY(EOMONTH(AS3,0)) -> 28 | ... AV6: =DAY(EOMONTH(AV3,0)) -> 31 | AW6: =DAY(EOMONTH(BB3,0)) -> 30 | AX6: =DAY(EOMONTH(AX3,0)) -> 31 | AY6: =DAY(EOMONTH(AY3,0)) -> 31 | AZ6: =DAY(EOMONTH(AZ3,0)) -> 30 | BA6: =DAY(EOMONTH(BA3,0)) -> 31 | BB6: =DAY(EOMONTH(BB3,0)) -> 30 | BC6: =DAY(EOMONTH(BC3,0)) -> 31 | BD6: =DAY(EOMONTH(BD3,0)) -> 31 | BE6: =DAY(EOMONTH(BE3,0)) -> 28 | ... BH6: =DAY(EOMONTH(BH3,0)) -> 31 | BI6: =DAY(EOMONTH(BN3,0)) -> 30 | BJ6: =DAY(EOMONTH(BJ3,0)) -> 31 | BK6: =DAY(EOMONTH(BK3,0)) -> 31 | BL6: =DAY(EOMONTH(BL3,0)) -> 30 | BM6: =DAY(EOMONTH(BM3,0)) -> 31 | BN6: =DAY(EOMONTH(BN3,0)) -> 30 | BO6: =DAY(EOMONTH(BO3,0)) -> 31 | BP6: =DAY(EOMONTH(BP3,0)) -> 31 | BQ6: =DAY(EOMONTH(BQ3,0)) -> 31 | ... BT6: =DAY(EOMONTH(BT3,0)) -> 31 | BU6: =DAY(EOMONTH(BZ3,0)) -> 31
C7: 新增装机（MW） | H7: 55 | I7: 0 | J7: =汇总!D39 -> 0 | K7: 0 | L7: 0 | M7: =汇总!D40 -> 100 | P7: =汇总!D41 -> 0 | S7: =汇总!D42 -> 400 | V7: =汇总!D47 -> 0 | Y7: =汇总!D48 -> 100 | AB7: =汇总!D49 -> 100 | AE7: =汇总!D50 -> 100 | AH7: =汇总!D55 -> 0 | AK7: =汇总!D56 -> 100 | AN7: =汇总!D57 -> 0 | AQ7: =汇总!D58 -> 0
C8: 累计装机（MW） | G8: =G7 -> 0 | H8: =G8+H7 -> 55 | I8: =H8+I7 -> 55 | J8: =I8+J7 -> 55 | K8: =J8+K7 -> 55 | L8: =K8+L7 -> 55 | M8: =L8+M7 -> 155 | N8: =M8+N7 -> 155 | O8: =N8+O7 -> 155 | ... BO8: =BN8+BO7 -> 955
C9: 累计装机（MW）- annual cumulative average | S9: =SUMPRODUCT($H$8:S8,$H$6:S6)/365 -> 147.60274 | AE9: =SUMPRODUCT($T$8:AE8,$T$6:AE6)/365 -> 655.54795 | AQ9: =SUMPRODUCT($AF$8:AQ8,$AF$6:AQ6)/365 -> 915.9726
C10: 项目数量 | H10: {=G10+_xlfn.IFS(H7=0,0,H7<=100,1,H7<=200,2)} -> 1 | I10: {=H10+_xlfn.IFS(I7=0,0,I7<=100,1,I7<=200,2)} -> 1 | J10: {=I10+_xlfn.IFS(J7=0,0,J7<=100,1,J7<=200,2)} -> 1 | K10: {=J10+_xlfn.IFS(K7=0,0,K7<=100,1,K7<=200,2)} -> 1 | L10: {=K10+_xlfn.IFS(L7=0,0,L7<=100,1,L7<=200,2)} -> 1 | M10: {=L10+_xlfn.IFS(M7=0,0,M7<=100,1,M7<=200,2)} -> 2 | N10: {=M10+_xlfn.IFS(N7=0,0,N7<=100,1,N7<=200,2)} -> 2 | O10: {=N10+_xlfn.IFS(O7=0,0,O7<=100,1,O7<=200,2)} -> 2 | ... R10: {=Q10+_xlfn.IFS(R7=0,0,R7<=100,1,R7<=200,2)} -> 2 | S10: =S7/70 -> 5.7142857 | T10: {=S10+_xlfn.IFS(T7=0,0,T7<=100,1,T7<=200,2)} -> 5.7142857 | U10: {=T10+_xlfn.IFS(U7=0,0,U7<=100,1,U7<=200,2)} -> 5.7142857 | V10: {=U10+_xlfn.IFS(V7=0,0,V7<=100,1,V7<=200,2)} -> 5.7142857 | W10: {=V10+_xlfn.IFS(W7=0,0,W7<=100,1,W7<=200,2)} -> 5.7142857 | X10: {=W10+_xlfn.IFS(X7=0,0,X7<=100,1,X7<=200,2)} -> 5.7142857 | Y10: {=X10+_xlfn.IFS(Y7=0,0,Y7<=100,1,Y7<=200,2)} -> 6.7142857 | Z10: {=Y10+_xlfn.IFS(Z7=0,0,Z7<=100,1,Z7<=200,2)} -> 6.7142857 | AA10: {=Z10+_xlfn.IFS(AA7=0,0,AA7<=100,1,AA7<=200,2)} -> 6.7142857 | ... BO10: {=BN10+_xlfn.IFS(BO7=0,0,BO7<=100,1,BO7<=200,2)} -> 9.7142857
C11: 区域数量 | G11: =G10 -> 0 | H11: =H10 -> 1 | I11: =I10 -> 1 | J11: =J10 -> 1 | K11: =K10 -> 1 | L11: =L10 -> 1 | M11: =M10 -> 2 | N11: =M11 -> 2 | O11: =N11 -> 2 | P11: =O11 -> 2 | Q11: =P11 -> 2 | R11: =Q11 -> 2 | S11: =S10/2 -> 2.8571429 | T11: =S11 -> 2.8571429 | U11: =T11 -> 2.8571429 | V11: =U11 -> 2.8571429 | W11: =V11 -> 2.8571429 | X11: =W11 -> 2.8571429 | Y11: =X11+1 -> 3.8571429 | Z11: =Y11 -> 3.8571429 | AA11: =Z11 -> 3.8571429 | AB11: =AA11 -> 3.8571429 | AC11: =AB11 -> 3.8571429 | AD11: =AC11 -> 3.8571429 | AE11: =AD11 -> 3.8571429 | AF11: =AE11 -> 3.8571429 | AG11: =AF11 -> 3.8571429 | ... AP11: =AO11 -> 3.8571429 | AQ11: 4 | AR11: =AQ11 -> 4 | AS11: =AR11 -> 4 | AT11: =AS11 -> 4 | AU11: =AT11 -> 4 | AV11: =AU11 -> 4 | AW11: =AV11 -> 4 | AX11: =AW11 -> 4 | AY11: =AX11 -> 4 | ... BO11: =BN11 -> 4
C12: 平均单瓦股权价格（元/W) | F12: =汇总!$D$64 -> 2 | H12: =$F$12 -> 2 | I12: =$F$12 -> 2 | J12: =$F$12 -> 2 | K12: =$F$12 -> 2 | L12: =$F$12 -> 2 | M12: =$F$12 -> 2 | N12: =$F$12 -> 2 | O12: =$F$12 -> 2 | ... BO12: =$F$12 -> 2
C13: JV股权新增出资额（万元） | G13: 0 | H13: 0 | I13: =+I7*I12*100 -> 0 | J13: =+J7*J12*100 -> 0 | K13: =+K7*K12*100 -> 0 | L13: =+L7*L12*100 -> 0 | M13: =+M7*M12*100 -> 20000 | N13: =+N7*N12*100 -> 0 | O13: =+O7*O12*100 -> 0 | P13: =+P7*P12*100 -> 0 | ... BO13: =+BO7*BO12*100 -> 0
C14: JV股权累计出资额（万元） | G14: =8700 -> 8700 | H14: =G14+H13 -> 8700 | I14: =H14+I13 -> 8700 | J14: =I14+J13 -> 8700 | K14: =J14+K13 -> 8700 | L14: =K14+L13 -> 8700 | M14: =L14+M13 -> 28700 | N14: =M14+N13 -> 28700 | O14: =N14+O13 -> 28700 | ... BO14: =BN14+BO13 -> 188700
C16: 基金股权新增出资额（万元） | F16: 0.75 | G16: =G13*$F$16 -> 0 | H16: =H13*$F$16 -> 0 | I16: =I13*$F$16 -> 0 | J16: =J13*$F$16 -> 0 | K16: =K14*50% -> 4350 | L16: =L13*$F$16 -> 0 | M16: =M13*$F$16 -> 15000 | N16: =N13*$F$16 -> 0 | O16: =O13*$F$16 -> 0 | P16: =P13*$F$16 -> 0 | Q16: =Q13*$F$16 -> 0 | R16: =R13*$F$16 -> 0 | S16: =S13*$F$16 -> 60000 | ... BO16: =BO13*$F$16 -> 0
C17: 基金股权累计出资额（万元） | F17: 0.75 | G17: =G16 -> 0 | H17: =G17+H16 -> 0 | I17: =H17+I16 -> 0 | J17: =I17+J16 -> 0 | K17: =J17+K16 -> 4350 | L17: =K17+L16 -> 4350 | M17: =L17+M16 -> 19350 | N17: =M17+N16 -> 19350 | O17: =N17+O16 -> 19350 | ... BO17: =BN17+BO16 -> 139350
A18: 8 | C18: 基金费用新增出资额（万元） | G18: 0 | H18: 0 | I18: 0 | J18: 0 | K18: 500 | L18: 0 | M18: 0 | N18: 0 | O18: 0 | P18: 0 | Q18: 0 | R18: 0 | S18: 0 | T18: 200 | U18: 0 | V18: 0 | W18: 0 | X18: 0 | Y18: 0 | Z18: 0 | AA18: 0 | AB18: 0 | AC18: 0 | AD18: 0 | AE18: 0 | AF18: 200 | AG18: 0 | AH18: 0 | AI18: 0 | AJ18: 0 | AK18: 0 | AL18: 0 | AM18: 0 | AN18: 0 | AO18: 0 | AP18: 0 | AQ18: 0 | AR18: 200 | AS18: 0 | AT18: 0 | AU18: 0 | AV18: 0 | AW18: 0 | AX18: 0 | AY18: 0 | AZ18: 0 | BA18: 0 | BB18: 0 | BC18: 0 | BD18: 200 | BE18: 0 | BF18: 0 | BG18: 0 | BH18: 0 | BI18: 0 | BJ18: 0 | BK18: 0 | BL18: 0 | BM18: 0 | BN18: 0 | BO18: 0
A19: 8 | C19: 基金费用累计出资额（万元） | G19: =G18 -> 0 | H19: =G19+H18 -> 0 | I19: =H19+I18 -> 0 | J19: =I19+J18 -> 0 | K19: =J19+K18 -> 500 | L19: =K19+L18 -> 500 | M19: =L19+M18 -> 500 | N19: =M19+N18 -> 500 | O19: =N19+O18 -> 500 | ... BO19: =BN19+BO18 -> 1300
A20: 8 | C20: 基金基础管理费出资额（含税，万元） | F20: 0.7 | G20: =(G$17+G$19)/99%*1%*(DATE(YEAR(G$3),12,31)-G$3)/365 -> 0 | H20: =(H$17+H$19)/99%*1%*(DATE(YEAR(H$3),12,31)-H$3)/365*$F$20 -> 0 | I20: =(I$16+I$18)/99%*1%*(DATE(YEAR(I$3),12,31)-I$3)/365*$F$20 -> 0 | J20: =(J$16+J$18)/99%*1%*(DATE(YEAR(J$3),12,31)-J$3)/365*$F$20 -> 0 | K20: =(K$16+K$18)/99%*1%*(DATE(YEAR(K$3),12,31)-K$3)/365*$F$20 -> 25.743185 | L20: =(L$16+L$18)/99%*1%*(DATE(YEAR(L$3),12,31)-L$3)/365*$F$20 -> 0 | M20: =(M$16+M$18)/99%*1%*(DATE(YEAR(M$3),12,31)-M$3)/365*$F$20 -> 61.892902 | N20: =(N$16+N$18)/99%*1%*(DATE(YEAR(N$3),12,31)-N$3)/365*$F$20 -> 0 | O20: =(O$16+O$18)/99%*1%*(DATE(YEAR(O$3),12,31)-O$3)/365*$F$20 -> 0 | P20: =(P$16+P$18)/99%*1%*(DATE(YEAR(P$3),12,31)-P$3)/365*$F$20 -> 0 | ... S20: =(S$16+S$18)/99%*1%*(DATE(YEAR(S$3),12,31)-S$3)/365*$F$20 -> 34.86924 | T20: =(T$17+T$19)/99%*1%*(DATE(YEAR(T$3),12,31)-T$3)/365*$F$20 -> 564.45939 | U20: =U$16/99%*1%*(DATE(YEAR(U$3),12,31)-U$3)/365*$F$20 -> 0 | V20: =V$16/99%*1%*(DATE(YEAR(V$3),12,31)-V$3)/365*$F$20 -> 0 | W20: =W$16/99%*1%*(DATE(YEAR(W$3),12,31)-W$3)/365*$F$20 -> 0 | X20: =X$16/99%*1%*(DATE(YEAR(X$3),12,31)-X$3)/365*$F$20 -> 0 | Y20: =Y$16/99%*1%*(DATE(YEAR(Y$3),12,31)-Y$3)/365*$F$20 -> 61.892902 | Z20: =Z$16/99%*1%*(DATE(YEAR(Z$3),12,31)-Z$3)/365*$F$20 -> 0 | AA20: =AA$16/99%*1%*(DATE(YEAR(AA$3),12,31)-AA$3)/365*$F$20 -> 0 | AB20: =AB$16/99%*1%*(DATE(YEAR(AB$3),12,31)-AB$3)/365*$F$20 -> 35.159817 | ... AE20: =AE$16/99%*1%*(DATE(YEAR(AE$3),12,31)-AE$3)/365*$F$20 -> 8.7173101 | AF20: =AF$17/99%*1%*(DATE(YEAR(AF$3),12,31)-AF$3)/365*$F$20 -> 879.24242 | AG20: =AG$16/99%*1%*(DATE(YEAR(AG$3),12,31)-AG$3)/365*$F$20 -> 0 | AH20: =AH$16/99%*1%*(DATE(YEAR(AH$3),12,31)-AH$3)/365*$F$20 -> 0 | AI20: =AI$16/99%*1%*(DATE(YEAR(AI$3),12,31)-AI$3)/365*$F$20 -> 0 | AJ20: =AJ$16/99%*1%*(DATE(YEAR(AJ$3),12,31)-AJ$3)/365*$F$20 -> 0 | AK20: =AK$16/99%*1%*(DATE(YEAR(AP$3),12,31)-AP$3)/365*$F$20 -> 17.43462 | AL20: =AL$16/99%*1%*(DATE(YEAR(AQ$3),12,31)-AQ$3)/365*$F$20 -> 0 | AM20: =AM$16/99%*1%*(DATE(YEAR(AR$3),12,31)-AR$3)/365*$F$20 -> 0 | AN20: =AN$16/99%*1%*(DATE(YEAR(AS$3),12,31)-AS$3)/365*$F$20 -> 0 | AO20: =AO$16/99%*1%*(DATE(YEAR(AT$3),12,31)-AT$3)/365*$F$20 -> 0 | AP20: =AP$16/99%*1%*(DATE(YEAR(AU$3),12,31)-AU$3)/365*$F$20 -> 0 | AQ20: =AQ$16/99%*1%*(DATE(YEAR(AV$3),12,31)-AV$3)/365*$F$20 -> 0 | AR20: =AR$16/99%*1%*(DATE(YEAR(AW$3),12,31)-AW$3)/365*$F$20 -> 0 | ... BO20: =BO$16/99%*1%*(DATE(YEAR(BT$3),12,31)-BT$3)/365*$F$20 -> 0
A21: 8 | C21: 基金激励管理费出资额（含税，万元） | D21: “1”为支付，"0"为不支付 | E21: =汇总!E65 -> 0 | F21: 0.3 | G21: 0 | H21: =(H$17+H$19)/99%*1%*(DATE(YEAR(H$3),12,31)-H$3)/365*$F$21*$E$21 -> 0 | I21: =(I$16+I$18)/99%*1%*(DATE(YEAR(I$3),12,31)-I$3)/365*$F$21*$E$21 -> 0 | J21: =(J$16+J$18)/99%*1%*(DATE(YEAR(J$3),12,31)-J$3)/365*$F$21*$E$21 -> 0 | K21: =(K$16+K$18)/99%*1%*(DATE(YEAR(K$3),12,31)-K$3)/365*$F$21*$E$21 -> 0 | L21: =(L$16+L$18)/99%*1%*(DATE(YEAR(L$3),12,31)-L$3)/365*$F$21*$E$21 -> 0 | M21: =(M$16+M$18)/99%*1%*(DATE(YEAR(M$3),12,31)-M$3)/365*$F$21*$E$21 -> 0 | N21: =(N$16+N$18)/99%*1%*(DATE(YEAR(N$3),12,31)-N$3)/365*$F$21*$E$21 -> 0 | O21: =(O$16+O$18)/99%*1%*(DATE(YEAR(O$3),12,31)-O$3)/365*$F$21*$E$21 -> 0 | P21: =(P$16+P$18)/99%*1%*(DATE(YEAR(P$3),12,31)-P$3)/365*$F$21*$E$21 -> 0 | ... S21: =(S$16+S$18)/99%*1%*(DATE(YEAR(S$3),12,31)-S$3)/365*$F$21*$E$21 -> 0 | T21: =(T$17+T$19)/99%*1%*(DATE(YEAR(T$3),12,31)-T$3)/365*$F$21*$E$21 -> 0 | U21: =(U$16+U$18)/99%*1%*(DATE(YEAR(U$3),12,31)-U$3)/365*$F$21*$E$21 -> 0 | V21: =(V$16+V$18)/99%*1%*(DATE(YEAR(V$3),12,31)-V$3)/365*$F$21*$E$21 -> 0 | W21: =(W$16+W$18)/99%*1%*(DATE(YEAR(W$3),12,31)-W$3)/365*$F$21*$E$21 -> 0 | X21: =(X$16+X$18)/99%*1%*(DATE(YEAR(X$3),12,31)-X$3)/365*$F$21*$E$21 -> 0 | Y21: =(Y$16+Y$18)/99%*1%*(DATE(YEAR(Y$3),12,31)-Y$3)/365*$F$21*$E$21 -> 0 | Z21: =(Z$16+Z$18)/99%*1%*(DATE(YEAR(Z$3),12,31)-Z$3)/365*$F$21*$E$21 -> 0 | AA21: =(AA$16+AA$18)/99%*1%*(DATE(YEAR(AA$3),12,31)-AA$3)/365*$F$21*$E$21 -> 0 | AB21: =(AB$16+AB$18)/99%*1%*(DATE(YEAR(AB$3),12,31)-AB$3)/365*$F$21*$E$21 -> 0 | ... AE21: =(AE$16+AE$18)/99%*1%*(DATE(YEAR(AE$3),12,31)-AE$3)/365*$F$21*$E$21 -> 0 | AF21: =(AF$17+AF$19)/99%*1%*(DATE(YEAR(AF$3),12,31)-AF$3)/365*$F$21*$E21 -> 0 | AG21: =AG$16/99%*1%*(DATE(YEAR(AG$3),12,31)-AG$3)/365*$F$21 -> 0 | AH21: =AH$16/99%*1%*(DATE(YEAR(AH$3),12,31)-AH$3)/365*$F$21 -> 0 | AI21: =AI$16/99%*1%*(DATE(YEAR(AI$3),12,31)-AI$3)/365*$F$21 -> 0 | AJ21: =AJ$16/99%*1%*(DATE(YEAR(AJ$3),12,31)-AJ$3)/365*$F$21 -> 0 | AK21: =(AK$16+AK$18)/99%*1%*(DATE(YEAR(AP$3),12,31)-AP$3)/365*$F$21*$E$21 -> 0 | AL21: =(AL$16+AL$18)/99%*1%*(DATE(YEAR(AQ$3),12,31)-AQ$3)/365*$F$21*$E$21 -> 0 | AM21: =(AM$16+AM$18)/99%*1%*(DATE(YEAR(AR$3),12,31)-AR$3)/365*$F$21*$E$21 -> 0 | AN21: =(AN$16+AN$18)/99%*1%*(DATE(YEAR(AS$3),12,31)-AS$3)/365*$F$21*$E$21 -> 0 | AO21: =(AO$16+AO$18)/99%*1%*(DATE(YEAR(AT$3),12,31)-AT$3)/365*$F$21*$E$21 -> 0 | AP21: =(AP$16+AP$18)/99%*1%*(DATE(YEAR(AU$3),12,31)-AU$3)/365*$F$21*$E$21 -> 0 | AQ21: =(AQ$16+AQ$18)/99%*1%*(DATE(YEAR(AV$3),12,31)-AV$3)/365*$F$21*$E$21 -> 0 | AR21: =(AR$16+AR$18)/99%*1%*(DATE(YEAR(AW$3),12,31)-AW$3)/365*$F$21*$E$21 -> 0 | ... BO21: =(BO$16+BO$18)/99%*1%*(DATE(YEAR(BT$3),12,31)-BT$3)/365*$F$21*$E$21 -> 0
C22: 基金新增总出资额（万元） | G22: =SUM(G16,G20:G21) -> 0 | H22: =SUM(H16,H20:H21) -> 0 | I22: =SUM(I16,I20:I21) -> 0 | J22: =SUM(J16,J20:J21) -> 0 | K22: =SUM(K16,K18,K20:K21) -> 4875.7432 | L22: =SUM(L16,L18,L20:L21) -> 0 | M22: =SUM(M16,M18,M20:M21) -> 15061.893 | N22: =SUM(N16,N18,N20:N21) -> 0 | O22: =SUM(O16,O18,O20:O21) -> 0 | P22: =SUM(P16,P18,P20:P21) -> 0 | Q22: =SUM(Q16,Q18,Q20:Q21) -> 0 | R22: =SUM(R16,R18,R20:R21) -> 0 | ... BO22: =SUM(BO16,BO18,BO20:BO21) -> 0
C23: 基金累计总出资额（万元） | D23: 认缴资本 | E23: 150000 | F23: 1 | G23: =G22 -> 0 | H23: =G23+H22 -> 0 | I23: =H23+I22 -> 0 | J23: =I23+J22 -> 0 | K23: =J23+K22 -> 4875.7432 | L23: =K23+L22 -> 4875.7432 | M23: =L23+M22 -> 19937.636 | N23: =M23+N22 -> 19937.636 | O23: =N23+O22 -> 19937.636 | ... BO23: =BN23+BO22 -> 142339.41
C24: 基金累计总出资% | G24: =G23/$E$23 -> 0 | H24: =H23/$E$23 -> 0 | I24: =I23/$E$23 -> 0 | J24: =J23/$E$23 -> 0 | K24: =K23/$E$23 -> 0.032504955 | L24: =L23/$E$23 -> 0.032504955 | M24: =M23/$E$23 -> 0.13291757 | N24: =N23/$E$23 -> 0.13291757 | ... BO24: =BO23/$E$23 -> 0.94892941
A26: 4 | C26: ACPL新增出资额（万元） | D26: ACPL | E26: 2250 | F26: =E26/150000 -> 0.015 | G26: 0 | H26: 0 | I26: 0 | J26: =基金资金安排!C22 -> 780 | K26: =IF(($F26*K$23-J27)<0,0,($F26*K$23-J27)) -> 0 | L26: =IF(($F26*L$23-K27)<0,0,($F26*L$23-K27)) -> 0 | M26: =IF(($F26*M$23-L27)<0,0,($F26*M$23-L27)) -> 0 | N26: =IF(($F26*N$23-M27)<0,0,($F26*N$23-M27)) -> 0 | O26: =IF(($F26*O$23-N27)<0,0,($F26*O$23-N27)) -> 0 | P26: =IF(($F26*P$23-O27)<0,0,($F26*P$23-O27)) -> 0 | Q26: =IF(($F26*Q$23-P27)<0,0,($F26*Q$23-P27)) -> 0 | R26: =IF(($F26*R$23-Q27)<0,0,($F26*R$23-Q27)) -> 0 | ... BO26: =IF(($F26*BO$23-BN27)<0,0,($F26*BO$23-BN27)) -> 0
A27: 4 | C27: ACPL累计出资额（万元） | G27: =G26 -> 0 | H27: =G27+H26 -> 0 | I27: =H27+I26 -> 0 | J27: =I27+J26 -> 780 | K27: =J27+K26 -> 780 | L27: =K27+L26 -> 780 | M27: =L27+M26 -> 780 | N27: =M27+N26 -> 780 | O27: =N27+O26 -> 780 | ... BO27: =BN27+BO26 -> 2135.0912
C28: ACPLSZ新增出资额（万元） | D28: ACPLSZ | E28: 1250 | F28: =E28/150000 -> 0.0083333333 | G28: 0 | H28: 0 | I28: 0 | J28: =基金资金安排!C13 -> 237.5 | K28: =基金资金安排!H13 -> 127.55102 | L28: =IF(($F28*L$23-K29)<0,0,($F28*L$23-K29)) -> 0 | M28: =IF(($F28*M$23-L29)<0,0,($F28*M$23-L29)) -> 0 | N28: =IF(($F28*N$23-M29)<0,0,($F28*N$23-M29)) -> 0 | O28: =IF(($F28*O$23-N29)<0,0,($F28*O$23-N29)) -> 0 | P28: =IF(($F28*P$23-O29)<0,0,($F28*P$23-O29)) -> 0 | Q28: =IF(($F28*Q$23-P29)<0,0,($F28*Q$23-P29)) -> 0 | R28: =IF(($F28*R$23-Q29)<0,0,($F28*R$23-Q29)) -> 0 | S28: =IF(($F28*S$23-R29)<0,0,($F28*S$23-R29)) -> 301.38652 | ... BO28: =IF(($F28*BO$23-BN29)<0,0,($F28*BO$23-BN29)) -> 0
C29: ACPLSZ累计出资额（万元） | G29: =G28 -> 0 | H29: =G29+H28 -> 0 | I29: =H29+I28 -> 0 | J29: =I29+J28 -> 237.5 | K29: =J29+K28 -> 365.05102 | L29: =K29+L28 -> 365.05102 | M29: =L29+M28 -> 365.05102 | N29: =M29+N28 -> 365.05102 | O29: =N29+O28 -> 365.05102 | ... BO29: =BN29+BO28 -> 1186.1618
C30: ACPSZL新增出资额（万元） | D30: ACPSZL | E30: 675 | F30: =E30/150000 -> 0.0045 | G30: 0 | H30: 0 | I30: 0 | J30: =基金资金安排!C18 -> 202.04082 | K30: =IF(($F30*K$23-J31)<0,0,($F30*K$23-J31)) -> 0 | L30: =IF(($F30*L$23-K31)<0,0,($F30*L$23-K31)) -> 0 | M30: =IF(($F30*M$23-L31)<0,0,($F30*M$23-L31)) -> 0 | N30: =IF(($F30*N$23-M31)<0,0,($F30*N$23-M31)) -> 0 | O30: =IF(($F30*O$23-N31)<0,0,($F30*O$23-N31)) -> 0 | P30: =IF(($F30*P$23-O31)<0,0,($F30*P$23-O31)) -> 0 | Q30: =IF(($F30*Q$23-P31)<0,0,($F30*Q$23-P31)) -> 0 | R30: =IF(($F30*R$23-Q31)<0,0,($F30*R$23-Q31)) -> 0 | ... BO30: =IF(($F30*BO$23-BN31)<0,0,($F30*BO$23-BN31)) -> 0
A31: 11 | C31: ACPSZL累计出资额（万元） | G31: =G30 -> 0 | H31: =G31+H30 -> 0 | I31: =H31+I30 -> 0 | J31: =I31+J30 -> 202.04082 | K31: =J31+K30 -> 202.04082 | L31: =K31+L30 -> 202.04082 | M31: =L31+M30 -> 202.04082 | N31: =M31+N30 -> 202.04082 | O31: =N31+O30 -> 202.04082 | ... BO31: =BN31+BO30 -> 640.52735
A32: 4 | C32: 深圳新融新增出资额（万元） | D32: 深圳新融 | E32: 5000 | F32: =E32/150000 -> 0.033333333 | G32: 0 | H32: 0 | I32: 0 | J32: =基金资金安排!C7 -> 500 | K32: 1000 | L32: =IF(($F32*L$23-K33)<0,0,($F32*L$23-K33)) -> 0 | M32: =IF(($F32*M$23-L33)<0,0,($F32*M$23-L33)) -> 0 | N32: =IF(($F32*N$23-M33)<0,0,($F32*N$23-M33)) -> 0 | O32: =IF(($F32*O$23-N33)<0,0,($F32*O$23-N33)) -> 0 | P32: =IF(($F32*P$23-O33)<0,0,($F32*P$23-O33)) -> 0 | Q32: =IF(($F32*Q$23-P33)<0,0,($F32*Q$23-P33)) -> 0 | R32: =IF(($F32*R$23-Q33)<0,0,($F32*R$23-Q33)) -> 0 | S32: =IF(($F32*S$23-R33)<0,0,($F32*S$23-R33)) -> 1165.7502 | ... BO32: =IF(($F32*BO$23-BN33)<0,0,($F32*BO$23-BN33)) -> 0
A33: 4 | C33: 深圳新融累计出资额（万元） | G33: =G32 -> 0 | H33: =G33+H32 -> 0 | I33: =H33+I32 -> 0 | J33: =I33+J32 -> 500 | K33: =J33+K32 -> 1500 | L33: =K33+L32 -> 1500 | M33: =L33+M32 -> 1500 | N33: =M33+N32 -> 1500 | O33: =N33+O32 -> 1500 | ... BO33: =BN33+BO32 -> 4744.6471
A34: 19
A35: 32 | C35: MAA 基本收入（含税，万元） | F35: =汇总!$D$66 -> 0.1 | G35: =F35*5500 -> 550 | H35: =H$8*$F35*100*H$4/4+H$7*$F35*100*(DATE(YEAR(H$3),INT((MONTH(H$3)-1)/3)*3+4,0)-H$3)/365*H$5 -> 137.5 | I35: =I$8*$F35*100*I$4/4+I$7*$F35*100*(DATE(YEAR(I$3),INT((MONTH(I$3)-1)/3)*3+4,0)-I$3)/365*I$5 -> 0 | J35: =J$8*$F35*100*J$4/4+J$7*$F35*100*(DATE(YEAR(J$3),INT((MONTH(J$3)-1)/3)*3+4,0)-J$3)/365*J$5 -> 0 | K35: =K$8*$F35*100*K$4/4+K$7*$F35*100*(DATE(YEAR(K$3),INT((MONTH(K$3)-1)/3)*3+4,0)-K$3)/365*K$5 -> 137.5 | L35: =L$8*$F35*100*L$4/4+L$7*$F35*100*(DATE(YEAR(L$3),INT((MONTH(L$3)-1)/3)*3+4,0)-L$3)/365*L$5 -> 0 | M35: =M$8*$F35*100*M$4/4+M$7*$F35*100*(DATE(YEAR(M$3),INT((MONTH(M$3)-1)/3)*3+4,0)-M$3)/365*M$5 -> 79.452055 | N35: =N$8*$F35*100*N$4/4+N$7*$F35*100*(DATE(YEAR(N$3),INT((MONTH(N$3)-1)/3)*3+4,0)-N$3)/365*N$5 -> 387.5 | O35: =O$8*$F35*100*O$4/4+O$7*$F35*100*(DATE(YEAR(O$3),INT((MONTH(O$3)-1)/3)*3+4,0)-O$3)/365*O$5 -> 0 | ... AJ35: =AJ$8*$F35*100*AJ$4/4+AJ$7*$F35*100*(DATE(YEAR(AJ$3),INT((MONTH(AJ$3)-1)/3)*3+4,0)-AJ$3)/365*AJ$5 -> 0 | AK35: =AK$8*$F35*100*AK$4/4+AK$7*$F35*100*(DATE(YEAR(AP$3),INT((MONTH(AP$3)-1)/3)*3+4,0)-AP$3)/365*AK$5 -> 164.38356 | AL35: =AL$8*$F35*100*AL$4/4+AL$7*$F35*100*(DATE(YEAR(AQ$3),INT((MONTH(AQ$3)-1)/3)*3+4,0)-AQ$3)/365*AL$5 -> 2387.5 | AM35: =AM$8*$F35*100*AM$4/4+AM$7*$F35*100*(DATE(YEAR(AR$3),INT((MONTH(AR$3)-1)/3)*3+4,0)-AR$3)/365*AM$5 -> 0 | AN35: =AN$8*$F35*100*AN$4/4+AN$7*$F35*100*(DATE(YEAR(AS$3),INT((MONTH(AS$3)-1)/3)*3+4,0)-AS$3)/365*AN$5 -> 0 | AO35: =AO$8*$F35*100*AO$4/4+AO$7*$F35*100*(DATE(YEAR(AT$3),INT((MONTH(AT$3)-1)/3)*3+4,0)-AT$3)/365*AO$5 -> 2387.5 | AP35: =AP$8*$F35*100*AP$4/4+AP$7*$F35*100*(DATE(YEAR(AU$3),INT((MONTH(AU$3)-1)/3)*3+4,0)-AU$3)/365*AP$5 -> 0 | AQ35: =AQ$8*$F35*100*AQ$4/4+AQ$7*$F35*100*(DATE(YEAR(AV$3),INT((MONTH(AV$3)-1)/3)*3+4,0)-AV$3)/365*AQ$5 -> 0 | AR35: =AR$8*$F35*100*AR$4/4+AR$7*$F35*100*(DATE(YEAR(AW$3),INT((MONTH(AW$3)-1)/3)*3+4,0)-AW$3)/365*AR$5 -> 2387.5 | ... BO35: =BO$8*$F35*100*BO$4/4+BO$7*$F35*100*(DATE(YEAR(BT$3),INT((MONTH(BT$3)-1)/3)*3+4,0)-BT$3)/365*BO$5 -> 0
A36: 32 | C36: MAA 激励收入一（含税，万元） | D36: “1”为支付，"0"为不支付 | E36: =汇总!E67 -> 0 | F36: =汇总!$D$67 -> 0.01 | G36: =G$8*$F36*100*(DATE(2025,12,31)-DATE(2024,12,16))/365 -> 0 | T36: {=SUMPRODUCT(H$8:S$8,I$3:T$3-H$3:S$3)/(T$3-H$3)*100*$F36*$E$36} -> 0 | AF36: {=SUMPRODUCT(T$8:AE$8,U$3:AF$3-T$3:AE$3)/(AF$3-T$3)*100*$F36*$E$36} -> 0
C37: MAA 激励收入二（含税，万元） | D37: “1”为支付，"0"为不支付 | E37: =汇总!E68 -> 0 | F37: =汇总!$D$68 -> 0.04 | G37: =G$8*$F37*100*(DATE(2025,12,31)-DATE(2024,12,16))/365 -> 0 | T37: {=SUMPRODUCT(H$8:S$8,I$3:T$3-H$3:S$3)/(T$3-H$3)*100*$F37*$E$37} -> 0 | AF37: {=SUMPRODUCT(T$8:AE$8,U$3:AF$3-T$3:AE$3)/(AF$3-T$3)*100*$F37*$E$37} -> 0
A38: 32 | C38: 总MAA收入（含税，万元） | G38: =SUM(G35:G37) -> 550 | H38: =SUM(H35:H37) -> 137.5 | I38: =SUM(I35:I37) -> 0 | J38: =SUM(J35:J37) -> 0 | K38: =SUM(K35:K37) -> 137.5 | L38: =SUM(L35:L37) -> 0 | M38: =SUM(M35:M37) -> 79.452055 | N38: =SUM(N35:N37) -> 387.5 | ... BO38: =SUM(BO35:BO37) -> 0
A40: 32 | C40: MAA 基本收入（不含税，万元） | D40: VAT | E40: 0.06 | F40: 0.12 | G40: =G35/(1+$E40) -> 518.86792 | H40: =H35/(1+$E40) -> 129.71698 | I40: =I35/(1+$E40) -> 0 | J40: =J35/(1+$E40) -> 0 | K40: =K35/(1+$E40) -> 129.71698 | L40: =L35/(1+$E40) -> 0 | M40: =M35/(1+$E40) -> 74.954769 | N40: =N35/(1+$E40) -> 365.56604 | ... BO40: =BO35/(1+$E40) -> 0
A41: 32 | C41: MAA 激励收入一（不含税，万元） | D41: VAT | E41: 0.06 | F41: 0.01 | G41: =G36/(1+$E41) -> 0 | H41: =H36/(1+$E41) -> 0 | I41: =I36/(1+$E41) -> 0 | J41: =J36/(1+$E41) -> 0 | K41: =K36/(1+$E41) -> 0 | L41: =L36/(1+$E41) -> 0 | M41: =M36/(1+$E41) -> 0 | N41: =N36/(1+$E41) -> 0 | ... BO41: =BO36/(1+$E41) -> 0
C42: MAA 激励收入二（不含税，万元） | D42: VAT | E42: 0.06 | F42: 0.02 | G42: =G37/(1+$E42) -> 0 | H42: =H37/(1+$E42) -> 0 | I42: =I37/(1+$E42) -> 0 | J42: =J37/(1+$E42) -> 0 | K42: =K37/(1+$E42) -> 0 | L42: =L37/(1+$E42) -> 0 | M42: =M37/(1+$E42) -> 0 | N42: =N37/(1+$E42) -> 0 | ... BO42: =BO37/(1+$E42) -> 0
A43: 32 | C43: 总MAA收入（不含税，万元） | D43: VAT | E43: 0.06 | G43: =SUM(G40:G42) -> 518.86792 | H43: =SUM(H40:H42) -> 129.71698 | I43: =SUM(I40:I42) -> 0 | J43: =SUM(J40:J42) -> 0 | K43: =SUM(K40:K42) -> 129.71698 | L43: =SUM(L40:L42) -> 0 | M43: =SUM(M40:M42) -> 74.954769 | N43: =SUM(N40:N42) -> 365.56604 | ... BO43: =SUM(BO40:BO42) -> 0
